<?xml version="1.0" ?>
<robot name="nightmare" xmlns:xacro="http://www.ros.org/wiki/xacro">

<xacro:include filename="$(find nightmare_description)/urdf/materials.xacro" />
<xacro:include filename="$(find nightmare_description)/urdf/nightmare.trans" />
<xacro:include filename="$(find nightmare_description)/urdf/nightmare.gazebo" />

<link name="base_link">
</link>

<link name="body_link">
  <inertial>
    <origin rpy="0 0 0" xyz="-5.6090748801665625e-05 -0.00769173581431502 0.01843556378112976"/>
    <mass value="5.613817329636711"/>
    <inertia ixx="0.03185" ixy="2.4e-05" ixz="-4e-06" iyy="0.013431" iyz="0.000255" izz="0.04215"/>
  </inertial>
  <visual>
    <origin rpy="0 0 0" xyz="0 0 0"/>
    <geometry>
      <mesh filename="package://nightmare_description/meshes/base_link.stl" scale="0.001 0.001 0.001"/>
    </geometry>
    <material name="silver"/>
  </visual>
  <collision>
    <origin rpy="0 0 0" xyz="0 0 0"/>
    <geometry>
      <mesh filename="package://nightmare_description/meshes/base_link.stl" scale="0.001 0.001 0.001"/>
    </geometry>
  </collision>
</link>

<link name="leg_1_tibia_1">
  <inertial>
    <origin rpy="0 0 0" xyz="0.04178343647128775 0.01550414301375086 -0.024598215230103873"/>
    <mass value="0.9419903891385216"/>
    <inertia ixx="0.001888" ixy="-0.000473" ixz="0.000754" iyy="0.001914" iyz="0.000727" izz="0.001093"/>
  </inertial>
  <visual>
    <origin rpy="0 0 0" xyz="-0.107917 -0.144991 -0.120366"/>
    <geometry>
      <mesh filename="package://nightmare_description/meshes/leg_1_tibia_1.stl" scale="0.001 0.001 0.001"/>
    </geometry>
    <material name="silver"/>
  </visual>
  <collision>
    <origin rpy="0 0 0" xyz="-0.107917 -0.144991 -0.120366"/>
    <geometry>
      <mesh filename="package://nightmare_description/meshes/leg_1_tibia_1.stl" scale="0.001 0.001 0.001"/>
    </geometry>
  </collision>
</link>

<link name="leg_1_coxa_1">
  <inertial>
    <origin rpy="0 0 0" xyz="0.02419335787837043 0.023903585464848637 -0.016051474178131547"/>
    <mass value="0.35112711988344936"/>
    <inertia ixx="0.000102" ixy="-6e-06" ixz="-2e-06" iyy="0.000103" iyz="-1e-06" izz="7.7e-05"/>
  </inertial>
  <visual>
    <origin rpy="0 0 0" xyz="-0.067171 -0.079498 -0.0455"/>
    <geometry>
      <mesh filename="package://nightmare_description/meshes/leg_1_coxa_1.stl" scale="0.001 0.001 0.001"/>
    </geometry>
    <material name="silver"/>
  </visual>
  <collision>
    <origin rpy="0 0 0" xyz="-0.067171 -0.079498 -0.0455"/>
    <geometry>
      <mesh filename="package://nightmare_description/meshes/leg_1_coxa_1.stl" scale="0.001 0.001 0.001"/>
    </geometry>
  </collision>
</link>

<link name="leg_2_tibia_1">
  <inertial>
    <origin rpy="0 0 0" xyz="0.0405095296195255 -0.01741506544088068 -0.024599997325444017"/>
    <mass value="0.9420449187889018"/>
    <inertia ixx="0.001428" ixy="-1.3e-05" ixz="0.001047" iyy="0.002374" iyz="1.8e-05" izz="0.001093"/>
  </inertial>
  <visual>
    <origin rpy="0 0 0" xyz="-0.168122 -0.0165 -0.120366"/>
    <geometry>
      <mesh filename="package://nightmare_description/meshes/leg_2_tibia_1.stl" scale="0.001 0.001 0.001"/>
    </geometry>
    <material name="silver"/>
  </visual>
  <collision>
    <origin rpy="0 0 0" xyz="-0.168122 -0.0165 -0.120366"/>
    <geometry>
      <mesh filename="package://nightmare_description/meshes/leg_2_tibia_1.stl" scale="0.001 0.001 0.001"/>
    </geometry>
  </collision>
</link>

<link name="leg_2_coxa_1">
  <inertial>
    <origin rpy="0 0 0" xyz="0.03400964092586298 0.00020422845539291943 -0.01605147332435354"/>
    <mass value="0.3511271309291035"/>
    <inertia ixx="9.7e-05" ixy="-0.0" ixz="-2e-06" iyy="0.000109" iyz="-0.0" izz="7.7e-05"/>
  </inertial>
  <visual>
    <origin rpy="0 0 0" xyz="-0.093 0.0 -0.0455"/>
    <geometry>
      <mesh filename="package://nightmare_description/meshes/leg_2_coxa_1.stl" scale="0.001 0.001 0.001"/>
    </geometry>
    <material name="silver"/>
  </visual>
  <collision>
    <origin rpy="0 0 0" xyz="-0.093 0.0 -0.0455"/>
    <geometry>
      <mesh filename="package://nightmare_description/meshes/leg_2_coxa_1.stl" scale="0.001 0.001 0.001"/>
    </geometry>
  </collision>
</link>

<link name="leg_3_tibia_1">
  <inertial>
    <origin rpy="0 0 0" xyz="0.01632987875460226 -0.04095773841364264 -0.024599412902793244"/>
    <mass value="0.9420254589050608"/>
    <inertia ixx="0.001888" ixy="0.000473" ixz="0.000754" iyy="0.001914" iyz="-0.000727" izz="0.001093"/>
  </inertial>
  <visual>
    <origin rpy="0 0 0" xyz="-0.131958 0.12095 -0.120366"/>
    <geometry>
      <mesh filename="package://nightmare_description/meshes/leg_3_tibia_1.stl" scale="0.001 0.001 0.001"/>
    </geometry>
    <material name="silver"/>
  </visual>
  <collision>
    <origin rpy="0 0 0" xyz="-0.131958 0.12095 -0.120366"/>
    <geometry>
      <mesh filename="package://nightmare_description/meshes/leg_3_tibia_1.stl" scale="0.001 0.001 0.001"/>
    </geometry>
  </collision>
</link>

<link name="leg_3_coxa_1">
  <inertial>
    <origin rpy="0 0 0" xyz="0.02419335787837036 -0.023903585464848692 -0.016051474178131506"/>
    <mass value="0.35112711988344947"/>
    <inertia ixx="0.000102" ixy="6e-06" ixz="-2e-06" iyy="0.000103" iyz="1e-06" izz="7.7e-05"/>
  </inertial>
  <visual>
    <origin rpy="0 0 0" xyz="-0.067171 0.079498 -0.0455"/>
    <geometry>
      <mesh filename="package://nightmare_description/meshes/leg_3_coxa_1.stl" scale="0.001 0.001 0.001"/>
    </geometry>
    <material name="silver"/>
  </visual>
  <collision>
    <origin rpy="0 0 0" xyz="-0.067171 0.079498 -0.0455"/>
    <geometry>
      <mesh filename="package://nightmare_description/meshes/leg_3_coxa_1.stl" scale="0.001 0.001 0.001"/>
    </geometry>
  </collision>
</link>

<link name="leg_4_tibia_1">
  <inertial>
    <origin rpy="0 0 0" xyz="-0.04178509143189514 -0.01550252573635652 -0.02459941290280207"/>
    <mass value="0.9420254589050611"/>
    <inertia ixx="0.001888" ixy="-0.000473" ixz="-0.000754" iyy="0.001914" iyz="-0.000727" izz="0.001093"/>
  </inertial>
  <visual>
    <origin rpy="0 0 0" xyz="0.107917 0.144991 -0.120366"/>
    <geometry>
      <mesh filename="package://nightmare_description/meshes/leg_4_tibia_1.stl" scale="0.001 0.001 0.001"/>
    </geometry>
    <material name="silver"/>
  </visual>
  <collision>
    <origin rpy="0 0 0" xyz="0.107917 0.144991 -0.120366"/>
    <geometry>
      <mesh filename="package://nightmare_description/meshes/leg_4_tibia_1.stl" scale="0.001 0.001 0.001"/>
    </geometry>
  </collision>
</link>

<link name="leg_4_femur_1">
  <inertial>
    <origin rpy="0 0 0" xyz="-0.02693213997445433 -0.0005002719623741908 0.05329446816033774"/>
    <mass value="0.13689906161265003"/>
    <inertia ixx="0.000164" ixy="1.2e-05" ixz="3.2e-05" iyy="0.000164" iyz="3.2e-05" izz="6.7e-05"/>
  </inertial>
  <visual>
    <origin rpy="0 0 0" xyz="0.081314 0.118388 -0.017"/>
    <geometry>
      <mesh filename="package://nightmare_description/meshes/leg_4_femur_1.stl" scale="0.001 0.001 0.001"/>
    </geometry>
    <material name="silver"/>
  </visual>
  <collision>
    <origin rpy="0 0 0" xyz="0.081314 0.118388 -0.017"/>
    <geometry>
      <mesh filename="package://nightmare_description/meshes/leg_4_femur_1.stl" scale="0.001 0.001 0.001"/>
    </geometry>
  </collision>
</link>

<link name="leg_4_coxa_1">
  <inertial>
    <origin rpy="0 0 0" xyz="-0.024193357902577595 -0.02390358548632862 -0.016051473999717337"/>
    <mass value="0.3511271220544307"/>
    <inertia ixx="0.000102" ixy="-6e-06" ixz="2e-06" iyy="0.000103" iyz="1e-06" izz="7.7e-05"/>
  </inertial>
  <visual>
    <origin rpy="0 0 0" xyz="0.067171 0.079498 -0.0455"/>
    <geometry>
      <mesh filename="package://nightmare_description/meshes/leg_4_coxa_1.stl" scale="0.001 0.001 0.001"/>
    </geometry>
    <material name="silver"/>
  </visual>
  <collision>
    <origin rpy="0 0 0" xyz="0.067171 0.079498 -0.0455"/>
    <geometry>
      <mesh filename="package://nightmare_description/meshes/leg_4_coxa_1.stl" scale="0.001 0.001 0.001"/>
    </geometry>
  </collision>
</link>

<link name="leg_5_tibia_1">
  <inertial>
    <origin rpy="0 0 0" xyz="-0.040509529619527 0.018584933307422072 -0.02459999732544571"/>
    <mass value="0.9420449187889016"/>
    <inertia ixx="0.001428" ixy="1.3e-05" ixz="-0.001047" iyy="0.002374" iyz="1.8e-05" izz="0.001093"/>
  </inertial>
  <visual>
    <origin rpy="0 0 0" xyz="0.168122 0.0175 -0.120366"/>
    <geometry>
      <mesh filename="package://nightmare_description/meshes/leg_5_tibia_1.stl" scale="0.001 0.001 0.001"/>
    </geometry>
    <material name="silver"/>
  </visual>
  <collision>
    <origin rpy="0 0 0" xyz="0.168122 0.0175 -0.120366"/>
    <geometry>
      <mesh filename="package://nightmare_description/meshes/leg_5_tibia_1.stl" scale="0.001 0.001 0.001"/>
    </geometry>
  </collision>
</link>

<link name="leg_5_femur_1">
  <inertial>
    <origin rpy="0 0 0" xyz="-0.01939760292696563 0.01869071222781447 0.05329446835295956"/>
    <mass value="0.1368990938782139"/>
    <inertia ixx="0.000176" ixy="0.0" ixz="4.6e-05" iyy="0.000151" iyz="-0.0" izz="6.7e-05"/>
  </inertial>
  <visual>
    <origin rpy="0 0 0" xyz="0.1305 0.0175 -0.017"/>
    <geometry>
      <mesh filename="package://nightmare_description/meshes/leg_5_femur_1.stl" scale="0.001 0.001 0.001"/>
    </geometry>
    <material name="silver"/>
  </visual>
  <collision>
    <origin rpy="0 0 0" xyz="0.1305 0.0175 -0.017"/>
    <geometry>
      <mesh filename="package://nightmare_description/meshes/leg_5_femur_1.stl" scale="0.001 0.001 0.001"/>
    </geometry>
  </collision>
</link>

<link name="leg_5_coxa_1">
  <inertial>
    <origin rpy="0 0 0" xyz="-0.034009640942105374 0.00020422888767037946 -0.016051473831694755"/>
    <mass value="0.35112712726422335"/>
    <inertia ixx="9.7e-05" ixy="0.0" ixz="2e-06" iyy="0.000109" iyz="-0.0" izz="7.7e-05"/>
  </inertial>
  <visual>
    <origin rpy="0 0 0" xyz="0.093 0.0 -0.0455"/>
    <geometry>
      <mesh filename="package://nightmare_description/meshes/leg_5_coxa_1.stl" scale="0.001 0.001 0.001"/>
    </geometry>
    <material name="silver"/>
  </visual>
  <collision>
    <origin rpy="0 0 0" xyz="0.093 0.0 -0.0455"/>
    <geometry>
      <mesh filename="package://nightmare_description/meshes/leg_5_coxa_1.stl" scale="0.001 0.001 0.001"/>
    </geometry>
  </collision>
</link>

<link name="leg_6_tibia_1">
  <inertial>
    <origin rpy="0 0 0" xyz="-0.016328330575181238 0.040959248909850324 -0.024598215230095144"/>
    <mass value="0.9419903891385227"/>
    <inertia ixx="0.001888" ixy="0.000473" ixz="-0.000754" iyy="0.001914" iyz="0.000727" izz="0.001093"/>
  </inertial>
  <visual>
    <origin rpy="0 0 0" xyz="0.132665 -0.120243 -0.120366"/>
    <geometry>
      <mesh filename="package://nightmare_description/meshes/leg_6_tibia_1.stl" scale="0.001 0.001 0.001"/>
    </geometry>
    <material name="silver"/>
  </visual>
  <collision>
    <origin rpy="0 0 0" xyz="0.132665 -0.120243 -0.120366"/>
    <geometry>
      <mesh filename="package://nightmare_description/meshes/leg_6_tibia_1.stl" scale="0.001 0.001 0.001"/>
    </geometry>
  </collision>
</link>

<link name="leg_6_femur_1">
  <inertial>
    <origin rpy="0 0 0" xyz="-0.0007699272971616461 0.026662484639660658 0.0532944681603395"/>
    <mass value="0.13689906161264997"/>
    <inertia ixx="0.000164" ixy="-1.2e-05" ixz="3.2e-05" iyy="0.000164" iyz="-3.2e-05" izz="6.7e-05"/>
  </inertial>
  <visual>
    <origin rpy="0 0 0" xyz="0.106062 -0.09364 -0.017"/>
    <geometry>
      <mesh filename="package://nightmare_description/meshes/leg_6_femur_1.stl" scale="0.001 0.001 0.001"/>
    </geometry>
    <material name="silver"/>
  </visual>
  <collision>
    <origin rpy="0 0 0" xyz="0.106062 -0.09364 -0.017"/>
    <geometry>
      <mesh filename="package://nightmare_description/meshes/leg_6_femur_1.stl" scale="0.001 0.001 0.001"/>
    </geometry>
  </collision>
</link>

<link name="leg_6_coxa_1">
  <inertial>
    <origin rpy="0 0 0" xyz="-0.02419335787837036 0.023903585464848692 -0.01605147417813148"/>
    <mass value="0.35112711988344947"/>
    <inertia ixx="0.000102" ixy="6e-06" ixz="2e-06" iyy="0.000103" iyz="-1e-06" izz="7.7e-05"/>
  </inertial>
  <visual>
    <origin rpy="0 0 0" xyz="0.067171 -0.079498 -0.0455"/>
    <geometry>
      <mesh filename="package://nightmare_description/meshes/leg_6_coxa_1.stl" scale="0.001 0.001 0.001"/>
    </geometry>
    <material name="silver"/>
  </visual>
  <collision>
    <origin rpy="0 0 0" xyz="0.067171 -0.079498 -0.0455"/>
    <geometry>
      <mesh filename="package://nightmare_description/meshes/leg_6_coxa_1.stl" scale="0.001 0.001 0.001"/>
    </geometry>
  </collision>
</link>

<link name="leg_1_femur_1">
  <inertial>
    <origin rpy="0 0 0" xyz="0.02693213997445433 0.0005002719623741769 0.0532944681603377"/>
    <mass value="0.13689906161265003"/>
    <inertia ixx="0.000164" ixy="1.2e-05" ixz="-3.2e-05" iyy="0.000164" iyz="-3.2e-05" izz="6.7e-05"/>
  </inertial>
  <visual>
    <origin rpy="0 0 0" xyz="-0.081314 -0.118388 -0.017"/>
    <geometry>
      <mesh filename="package://nightmare_description/meshes/leg_1_femur_1.stl" scale="0.001 0.001 0.001"/>
    </geometry>
    <material name="silver"/>
  </visual>
  <collision>
    <origin rpy="0 0 0" xyz="-0.081314 -0.118388 -0.017"/>
    <geometry>
      <mesh filename="package://nightmare_description/meshes/leg_1_femur_1.stl" scale="0.001 0.001 0.001"/>
    </geometry>
  </collision>
</link>

<link name="leg_2_femur_1">
  <inertial>
    <origin rpy="0 0 0" xyz="0.019397602926964297 -0.018309286520488362 0.053294468352960034"/>
    <mass value="0.1368990938782139"/>
    <inertia ixx="0.000176" ixy="-0.0" ixz="-4.6e-05" iyy="0.000151" iyz="-0.0" izz="6.7e-05"/>
  </inertial>
  <visual>
    <origin rpy="0 0 0" xyz="-0.1305 -0.0165 -0.017"/>
    <geometry>
      <mesh filename="package://nightmare_description/meshes/leg_2_femur_1.stl" scale="0.001 0.001 0.001"/>
    </geometry>
    <material name="silver"/>
  </visual>
  <collision>
    <origin rpy="0 0 0" xyz="-0.1305 -0.0165 -0.017"/>
    <geometry>
      <mesh filename="package://nightmare_description/meshes/leg_2_femur_1.stl" scale="0.001 0.001 0.001"/>
    </geometry>
  </collision>
</link>

<link name="leg_3_femur_1">
  <inertial>
    <origin rpy="0 0 0" xyz="0.000769820515975031 -0.026662591420847162 0.053294468160339475"/>
    <mass value="0.13689906161264997"/>
    <inertia ixx="0.000164" ixy="-1.2e-05" ixz="-3.2e-05" iyy="0.000164" iyz="3.2e-05" izz="6.7e-05"/>
  </inertial>
  <visual>
    <origin rpy="0 0 0" xyz="-0.105355 0.094347 -0.017"/>
    <geometry>
      <mesh filename="package://nightmare_description/meshes/leg_3_femur_1.stl" scale="0.001 0.001 0.001"/>
    </geometry>
    <material name="silver"/>
  </visual>
  <collision>
    <origin rpy="0 0 0" xyz="-0.105355 0.094347 -0.017"/>
    <geometry>
      <mesh filename="package://nightmare_description/meshes/leg_3_femur_1.stl" scale="0.001 0.001 0.001"/>
    </geometry>
  </collision>
</link>

<link name="leg_1_tip">
</link>

<link name="leg_2_tip">
</link>

<link name="leg_3_tip">
</link>

<link name="leg_4_tip">
</link>

<link name="leg_5_tip">
</link>

<link name="leg_6_tip">
</link>

<joint name="base2body" type="fixed">
  <origin rpy="0 0 0" xyz="0 0 0"/>
  <parent link="base_link"/>
  <child link="body_link"/>
</joint>

<joint name="leg1tibia" type="continuous">
  <origin rpy="0 0 0" xyz="0.026603 0.026603 0.103366"/>
  <parent link="leg_1_femur_1"/>
  <child link="leg_1_tibia_1"/>
  <axis xyz="-0.707107 0.707107 0.0"/>
</joint>

<joint name="leg1coxa" type="continuous">
  <origin rpy="0 0 0" xyz="0.067171 0.079498 0.0455"/>
  <parent link="body_link"/>
  <child link="leg_1_coxa_1"/>
  <axis xyz="0.0 -0.0 -1.0"/>
</joint>

<joint name="leg2tibia" type="continuous">
  <origin rpy="0 0 0" xyz="0.037622 0.0 0.103366"/>
  <parent link="leg_2_femur_1"/>
  <child link="leg_2_tibia_1"/>
  <axis xyz="0.0 1.0 0.0"/>
</joint>

<joint name="leg2coxa" type="continuous">
  <origin rpy="0 0 0" xyz="0.093 0.0 0.0455"/>
  <parent link="body_link"/>
  <child link="leg_2_coxa_1"/>
  <axis xyz="-0.0 -0.0 -1.0"/>
</joint>

<joint name="leg3tibia" type="continuous">
  <origin rpy="0 0 0" xyz="0.026603 -0.026603 0.103366"/>
  <parent link="leg_3_femur_1"/>
  <child link="leg_3_tibia_1"/>
  <axis xyz="0.707107 0.707107 -0.0"/>
</joint>

<joint name="leg3coxa" type="continuous">
  <origin rpy="0 0 0" xyz="0.067171 -0.079498 0.0455"/>
  <parent link="body_link"/>
  <child link="leg_3_coxa_1"/>
  <axis xyz="-0.0 -0.0 -1.0"/>
</joint>

<joint name="leg4tibia" type="continuous">
  <origin rpy="0 0 0" xyz="-0.026603 -0.026603 0.103366"/>
  <parent link="leg_4_femur_1"/>
  <child link="leg_4_tibia_1"/>
  <axis xyz="0.707107 -0.707107 0.0"/>
</joint>

<joint name="leg4femur" type="continuous">
  <origin rpy="0 0 0" xyz="-0.014143 -0.03889 -0.0285"/>
  <parent link="leg_4_coxa_1"/>
  <child link="leg_4_femur_1"/>
  <axis xyz="-0.707107 0.707107 -0.0"/>
</joint>

<joint name="leg4coxa" type="continuous">
  <origin rpy="0 0 0" xyz="-0.067171 -0.079498 0.0455"/>
  <parent link="body_link"/>
  <child link="leg_4_coxa_1"/>
  <axis xyz="-0.0 0.0 -1.0"/>
</joint>

<joint name="leg5tibia" type="continuous">
  <origin rpy="0 0 0" xyz="-0.037622 0.0 0.103366"/>
  <parent link="leg_5_femur_1"/>
  <child link="leg_5_tibia_1"/>
  <axis xyz="0.0 -1.0 -0.0"/>
</joint>

<joint name="leg5femur" type="continuous">
  <origin rpy="0 0 0" xyz="-0.0375 -0.0175 -0.0285"/>
  <parent link="leg_5_coxa_1"/>
  <child link="leg_5_femur_1"/>
  <axis xyz="-0.0 1.0 0.0"/>
</joint>

<joint name="leg5coxa" type="continuous">
  <origin rpy="0 0 0" xyz="-0.093 0.0 0.0455"/>
  <parent link="body_link"/>
  <child link="leg_5_coxa_1"/>
  <axis xyz="-0.0 0.0 -1.0"/>
</joint>

<joint name="leg6tibia" type="continuous">
  <origin rpy="0 0 0" xyz="-0.026603 0.026603 0.103366"/>
  <parent link="leg_6_femur_1"/>
  <child link="leg_6_tibia_1"/>
  <axis xyz="-0.707107 -0.707107 -0.0"/>
</joint>

<joint name="leg6femur" type="continuous">
  <origin rpy="0 0 0" xyz="-0.038891 0.014142 -0.0285"/>
  <parent link="leg_6_coxa_1"/>
  <child link="leg_6_femur_1"/>
  <axis xyz="0.707107 0.707107 -0.0"/>
</joint>

<joint name="leg6coxa" type="continuous">
  <origin rpy="0 0 0" xyz="-0.067171 0.079498 0.0455"/>
  <parent link="body_link"/>
  <child link="leg_6_coxa_1"/>
  <axis xyz="0.0 0.0 -1.0"/>
</joint>

<joint name="leg1femur" type="continuous">
  <origin rpy="0 0 0" xyz="0.014143 0.03889 -0.0285"/>
  <parent link="leg_1_coxa_1"/>
  <child link="leg_1_femur_1"/>
  <axis xyz="0.707107 -0.707107 -0.0"/>
</joint>

<joint name="leg2femur" type="continuous">
  <origin rpy="0 0 0" xyz="0.0375 0.0165 -0.0285"/>
  <parent link="leg_2_coxa_1"/>
  <child link="leg_2_femur_1"/>
  <axis xyz="0.0 -1.0 0.0"/>
</joint>

<joint name="leg3femur" type="continuous">
  <origin rpy="0 0 0" xyz="0.038184 -0.014849 -0.0285"/>
  <parent link="leg_3_coxa_1"/>
  <child link="leg_3_femur_1"/>
  <axis xyz="-0.707107 -0.707107 -0.0"/>
</joint>

<joint name="leg1tip" type="fixed">
  <origin rpy="0 0 0" xyz="0.083143 0.055315 -0.13882"/>
  <parent link="leg_1_tibia_1"/>
  <child link="leg_1_tip"/>
</joint>

<joint name="leg2tip" type="fixed">
  <origin rpy="0 0 0" xyz="0.098086 -0.016834 -0.13945"/>
  <parent link="leg_2_tibia_1"/>
  <child link="leg_2_tip"/>
</joint>

<joint name="leg3tip" type="fixed">
  <origin rpy="0 0 0" xyz="0.057977 -0.080731 -0.13799"/>
  <parent link="leg_3_tibia_1"/>
  <child link="leg_3_tip"/>
</joint>

<joint name="leg4tip" type="fixed">
  <origin rpy="0 0 0" xyz="-0.083143 -0.055315 -0.13882"/>
  <parent link="leg_4_tibia_1"/>
  <child link="leg_4_tip"/>
</joint>

<joint name="leg5tip" type="fixed">
  <origin rpy="0 0 0" xyz="-0.098086 0.016834 -0.13945"/>
  <parent link="leg_5_tibia_1"/>
  <child link="leg_5_tip"/>
</joint>

<joint name="leg6tip" type="fixed">
  <origin rpy="0 0 0" xyz="-0.057977 0.080731 -0.13799"/>
  <parent link="leg_6_tibia_1"/>
  <child link="leg_6_tip"/>
</joint>

</robot>
