<?xml version="1.0" ?>
<robot name="nightmare_v2">
<link name="base_link">
  <visual>
    <origin rpy="0 0 0" xyz="0 0 0"/>
    <geometry>
      <mesh filename="package://nightmare_description/meshes/base_link.stl" scale="0.001 0.001 0.001"/>
    </geometry>
    <material name="silver">
      <color rgba="1 0 0 1"/>
    </material>
  </visual>
  <collision>
    <origin rpy="0 0 0" xyz="0 0 0"/>
    <geometry>
      <mesh filename="package://nightmare_description/meshes/base_link.stl" scale="0.001 0.001 0.001"/>
    </geometry>
  </collision>
</link>
<link name="leg_8_motor_1">
  <inertial>
    <origin rpy="0 0 0" xyz="-0.020134 -0.005284999999999998 -0.017272"/>
    <mass value="0.315076"/>
    <inertia ixx="7e-05" ixy="-1.9e-05" ixz="0.000291" iyy="7e-05" iyz="-0.000292" izz="6.9e-05"/>
  </inertial>
  <visual>
    <origin rpy="0 0 0" xyz="0.039681 0.099177 -0.038"/>
    <geometry>
      <mesh filename="package://nightmare_description/meshes/leg_8_motor_1.stl" scale="0.001 0.001 0.001"/>
    </geometry>
    <material name="silver">
      <color rgba="1 0 0 1"/>
    </material>
  </visual>
  <collision>
    <origin rpy="0 0 0" xyz="0.039681 0.099177 -0.038"/>
    <geometry>
      <mesh filename="package://nightmare_description/meshes/leg_8_motor_1.stl" scale="0.001 0.001 0.001"/>
    </geometry>
  </collision>
</link>
<link name="leg_1_motor_1">
  <inertial>
    <origin rpy="0 0 0" xyz="0.020134000000000006 -0.005284999999999998 -0.017272"/>
    <mass value="0.315076"/>
    <inertia ixx="7e-05" ixy="1.9e-05" ixz="0.00111" iyy="7e-05" iyz="-0.00111" izz="6.9e-05"/>
  </inertial>
  <visual>
    <origin rpy="0 0 0" xyz="-0.04251 0.102005 -0.038"/>
    <geometry>
      <mesh filename="package://nightmare_description/meshes/leg_1_motor_1.stl" scale="0.001 0.001 0.001"/>
    </geometry>
    <material name="silver">
      <color rgba="1 0 0 1"/>
    </material>
  </visual>
  <collision>
    <origin rpy="0 0 0" xyz="-0.04251 0.102005 -0.038"/>
    <geometry>
      <mesh filename="package://nightmare_description/meshes/leg_1_motor_1.stl" scale="0.001 0.001 0.001"/>
    </geometry>
  </collision>
</link>
<link name="tail_motor_1">
  <inertial>
    <origin rpy="0 0 0" xyz="-0.0105 -0.017974000000000018 -0.017272"/>
    <mass value="0.315076"/>
    <inertia ixx="8.8e-05" ixy="-0.0" ixz="0.000893" iyy="5.1e-05" iyz="-0.000893" izz="6.9e-05"/>
  </inertial>
  <visual>
    <origin rpy="0 0 0" xyz="-0.01025 0.119 -0.038"/>
    <geometry>
      <mesh filename="package://nightmare_description/meshes/tail_motor_1.stl" scale="0.001 0.001 0.001"/>
    </geometry>
    <material name="silver">
      <color rgba="1 0 0 1"/>
    </material>
  </visual>
  <collision>
    <origin rpy="0 0 0" xyz="-0.01025 0.119 -0.038"/>
    <geometry>
      <mesh filename="package://nightmare_description/meshes/tail_motor_1.stl" scale="0.001 0.001 0.001"/>
    </geometry>
  </collision>
</link>
<link name="leg_2_motor_1">
  <inertial>
    <origin rpy="0 0 0" xyz="0.019524 0.007219000000000003 -0.017272"/>
    <mass value="0.315076"/>
    <inertia ixx="5.2e-05" ixy="6e-06" ixz="0.000876" iyy="8.7e-05" iyz="-0.000876" izz="6.9e-05"/>
  </inertial>
  <visual>
    <origin rpy="0 0 0" xyz="-0.077311 0.044552 -0.038"/>
    <geometry>
      <mesh filename="package://nightmare_description/meshes/leg_2_motor_1.stl" scale="0.001 0.001 0.001"/>
    </geometry>
    <material name="silver">
      <color rgba="1 0 0 1"/>
    </material>
  </visual>
  <collision>
    <origin rpy="0 0 0" xyz="-0.077311 0.044552 -0.038"/>
    <geometry>
      <mesh filename="package://nightmare_description/meshes/leg_2_motor_1.stl" scale="0.001 0.001 0.001"/>
    </geometry>
  </collision>
</link>
<link name="leg_3_motor_1">
  <inertial>
    <origin rpy="0 0 0" xyz="0.019524 -0.007219000000000003 -0.017272"/>
    <mass value="0.315076"/>
    <inertia ixx="5.2e-05" ixy="-6e-06" ixz="0.000389" iyy="8.7e-05" iyz="-0.000388" izz="6.9e-05"/>
  </inertial>
  <visual>
    <origin rpy="0 0 0" xyz="-0.077311 -0.044552 -0.038"/>
    <geometry>
      <mesh filename="package://nightmare_description/meshes/leg_3_motor_1.stl" scale="0.001 0.001 0.001"/>
    </geometry>
    <material name="silver">
      <color rgba="1 0 0 1"/>
    </material>
  </visual>
  <collision>
    <origin rpy="0 0 0" xyz="-0.077311 -0.044552 -0.038"/>
    <geometry>
      <mesh filename="package://nightmare_description/meshes/leg_3_motor_1.stl" scale="0.001 0.001 0.001"/>
    </geometry>
  </collision>
</link>
<link name="leg_4_motor_1">
  <inertial>
    <origin rpy="0 0 0" xyz="0.020134000000000006 0.005284999999999998 -0.017272"/>
    <mass value="0.315076"/>
    <inertia ixx="7e-05" ixy="-1.9e-05" ixz="-0.000291" iyy="7e-05" iyz="0.000292" izz="6.9e-05"/>
  </inertial>
  <visual>
    <origin rpy="0 0 0" xyz="-0.04251 -0.102005 -0.038"/>
    <geometry>
      <mesh filename="package://nightmare_description/meshes/leg_4_motor_1.stl" scale="0.001 0.001 0.001"/>
    </geometry>
    <material name="silver">
      <color rgba="1 0 0 1"/>
    </material>
  </visual>
  <collision>
    <origin rpy="0 0 0" xyz="-0.04251 -0.102005 -0.038"/>
    <geometry>
      <mesh filename="package://nightmare_description/meshes/leg_4_motor_1.stl" scale="0.001 0.001 0.001"/>
    </geometry>
  </collision>
</link>
<link name="head_motor_pan_1">
  <inertial>
    <origin rpy="0 0 0" xyz="0.0105 0.017974000000000018 -0.017272"/>
    <mass value="0.315076"/>
    <inertia ixx="8.8e-05" ixy="-0.0" ixz="-0.000893" iyy="5.1e-05" iyz="0.000893" izz="6.9e-05"/>
  </inertial>
  <visual>
    <origin rpy="0 0 0" xyz="0.01025 -0.119 -0.038"/>
    <geometry>
      <mesh filename="package://nightmare_description/meshes/head_motor_pan_1.stl" scale="0.001 0.001 0.001"/>
    </geometry>
    <material name="silver">
      <color rgba="1 0 0 1"/>
    </material>
  </visual>
  <collision>
    <origin rpy="0 0 0" xyz="0.01025 -0.119 -0.038"/>
    <geometry>
      <mesh filename="package://nightmare_description/meshes/head_motor_pan_1.stl" scale="0.001 0.001 0.001"/>
    </geometry>
  </collision>
</link>
<link name="leg_5_motor_1">
  <inertial>
    <origin rpy="0 0 0" xyz="-0.020134000000000006 0.005284999999999998 -0.017272"/>
    <mass value="0.315076"/>
    <inertia ixx="7e-05" ixy="1.9e-05" ixz="-0.00111" iyy="7e-05" iyz="0.00111" izz="6.9e-05"/>
  </inertial>
  <visual>
    <origin rpy="0 0 0" xyz="0.04251 -0.102005 -0.038"/>
    <geometry>
      <mesh filename="package://nightmare_description/meshes/leg_5_motor_1.stl" scale="0.001 0.001 0.001"/>
    </geometry>
    <material name="silver">
      <color rgba="1 0 0 1"/>
    </material>
  </visual>
  <collision>
    <origin rpy="0 0 0" xyz="0.04251 -0.102005 -0.038"/>
    <geometry>
      <mesh filename="package://nightmare_description/meshes/leg_5_motor_1.stl" scale="0.001 0.001 0.001"/>
    </geometry>
  </collision>
</link>
<link name="leg_6_motor_1">
  <inertial>
    <origin rpy="0 0 0" xyz="-0.019524 -0.007219000000000003 -0.017272"/>
    <mass value="0.315076"/>
    <inertia ixx="5.2e-05" ixy="6e-06" ixz="-0.000876" iyy="8.7e-05" iyz="0.000876" izz="6.9e-05"/>
  </inertial>
  <visual>
    <origin rpy="0 0 0" xyz="0.077311 -0.044552 -0.038"/>
    <geometry>
      <mesh filename="package://nightmare_description/meshes/leg_6_motor_1.stl" scale="0.001 0.001 0.001"/>
    </geometry>
    <material name="silver">
      <color rgba="1 0 0 1"/>
    </material>
  </visual>
  <collision>
    <origin rpy="0 0 0" xyz="0.077311 -0.044552 -0.038"/>
    <geometry>
      <mesh filename="package://nightmare_description/meshes/leg_6_motor_1.stl" scale="0.001 0.001 0.001"/>
    </geometry>
  </collision>
</link>
<link name="leg_7_motor_1">
  <inertial>
    <origin rpy="0 0 0" xyz="-0.019524 0.007219000000000003 -0.017272"/>
    <mass value="0.315076"/>
    <inertia ixx="5.2e-05" ixy="-6e-06" ixz="-0.000389" iyy="8.7e-05" iyz="0.000388" izz="6.9e-05"/>
  </inertial>
  <visual>
    <origin rpy="0 0 0" xyz="0.077311 0.044552 -0.038"/>
    <geometry>
      <mesh filename="package://nightmare_description/meshes/leg_7_motor_1.stl" scale="0.001 0.001 0.001"/>
    </geometry>
    <material name="silver">
      <color rgba="1 0 0 1"/>
    </material>
  </visual>
  <collision>
    <origin rpy="0 0 0" xyz="0.077311 0.044552 -0.038"/>
    <geometry>
      <mesh filename="package://nightmare_description/meshes/leg_7_motor_1.stl" scale="0.001 0.001 0.001"/>
    </geometry>
  </collision>
</link>
<link name="leg_1_coxa_1">
  <inertial>
    <origin rpy="0 0 0" xyz="0.024053000000000005 -0.024052000000000004 -0.0205"/>
    <mass value="0.073783"/>
    <inertia ixx="3.2e-05" ixy="3e-06" ixz="0.000356" iyy="3.2e-05" iyz="-0.000356" izz="3.5e-05"/>
  </inertial>
  <visual>
    <origin rpy="0 0 0" xyz="-0.071147 0.115794 -0.041"/>
    <geometry>
      <mesh filename="package://nightmare_description/meshes/leg_1_coxa_1.stl" scale="0.001 0.001 0.001"/>
    </geometry>
    <material name="silver">
      <color rgba="1 0 0 1"/>
    </material>
  </visual>
  <collision>
    <origin rpy="0 0 0" xyz="-0.071147 0.115794 -0.041"/>
    <geometry>
      <mesh filename="package://nightmare_description/meshes/leg_1_coxa_1.stl" scale="0.001 0.001 0.001"/>
    </geometry>
  </collision>
</link>
<link name="leg_8_coxa_1">
  <inertial>
    <origin rpy="0 0 0" xyz="-0.02405199999999999 -0.024053000000000005 -0.0205"/>
    <mass value="0.073783"/>
    <inertia ixx="3.2e-05" ixy="-3e-06" ixz="6.8e-05" iyy="3.2e-05" iyz="-6.8e-05" izz="3.5e-05"/>
  </inertial>
  <visual>
    <origin rpy="0 0 0" xyz="0.068319 0.112965 -0.041"/>
    <geometry>
      <mesh filename="package://nightmare_description/meshes/leg_8_coxa_1.stl" scale="0.001 0.001 0.001"/>
    </geometry>
    <material name="silver">
      <color rgba="1 0 0 1"/>
    </material>
  </visual>
  <collision>
    <origin rpy="0 0 0" xyz="0.068319 0.112965 -0.041"/>
    <geometry>
      <mesh filename="package://nightmare_description/meshes/leg_8_coxa_1.stl" scale="0.001 0.001 0.001"/>
    </geometry>
  </collision>
</link>
<link name="leg_7_coxa_1">
  <inertial>
    <origin rpy="0 0 0" xyz="-0.033498 -0.0059070000000000025 -0.0205"/>
    <mass value="0.073783"/>
    <inertia ixx="3e-05" ixy="-1e-06" ixz="-0.000146" iyy="3.5e-05" iyz="0.000146" izz="3.5e-05"/>
  </inertial>
  <visual>
    <origin rpy="0 0 0" xyz="0.108679 0.039421 -0.041"/>
    <geometry>
      <mesh filename="package://nightmare_description/meshes/leg_7_coxa_1.stl" scale="0.001 0.001 0.001"/>
    </geometry>
    <material name="silver">
      <color rgba="1 0 0 1"/>
    </material>
  </visual>
  <collision>
    <origin rpy="0 0 0" xyz="0.108679 0.039421 -0.041"/>
    <geometry>
      <mesh filename="package://nightmare_description/meshes/leg_7_coxa_1.stl" scale="0.001 0.001 0.001"/>
    </geometry>
  </collision>
</link>
<link name="leg_6_coxa_1">
  <inertial>
    <origin rpy="0 0 0" xyz="-0.033498 0.0059070000000000025 -0.0205"/>
    <mass value="0.073783"/>
    <inertia ixx="3e-05" ixy="1e-06" ixz="-0.000284" iyy="3.5e-05" iyz="0.000284" izz="3.5e-05"/>
  </inertial>
  <visual>
    <origin rpy="0 0 0" xyz="0.108679 -0.039421 -0.041"/>
    <geometry>
      <mesh filename="package://nightmare_description/meshes/leg_6_coxa_1.stl" scale="0.001 0.001 0.001"/>
    </geometry>
    <material name="silver">
      <color rgba="1 0 0 1"/>
    </material>
  </visual>
  <collision>
    <origin rpy="0 0 0" xyz="0.108679 -0.039421 -0.041"/>
    <geometry>
      <mesh filename="package://nightmare_description/meshes/leg_6_coxa_1.stl" scale="0.001 0.001 0.001"/>
    </geometry>
  </collision>
</link>
<link name="leg_5_coxa_1">
  <inertial>
    <origin rpy="0 0 0" xyz="-0.024053000000000005 0.024052000000000004 -0.0205"/>
    <mass value="0.073783"/>
    <inertia ixx="3.2e-05" ixy="3e-06" ixz="-0.000356" iyy="3.2e-05" iyz="0.000356" izz="3.5e-05"/>
  </inertial>
  <visual>
    <origin rpy="0 0 0" xyz="0.071147 -0.115794 -0.041"/>
    <geometry>
      <mesh filename="package://nightmare_description/meshes/leg_5_coxa_1.stl" scale="0.001 0.001 0.001"/>
    </geometry>
    <material name="silver">
      <color rgba="1 0 0 1"/>
    </material>
  </visual>
  <collision>
    <origin rpy="0 0 0" xyz="0.071147 -0.115794 -0.041"/>
    <geometry>
      <mesh filename="package://nightmare_description/meshes/leg_5_coxa_1.stl" scale="0.001 0.001 0.001"/>
    </geometry>
  </collision>
</link>
<link name="leg_4_coxa_1">
  <inertial>
    <origin rpy="0 0 0" xyz="0.024053000000000005 0.024052000000000004 -0.0205"/>
    <mass value="0.073783"/>
    <inertia ixx="3.2e-05" ixy="-3e-06" ixz="-6.8e-05" iyy="3.2e-05" iyz="6.8e-05" izz="3.5e-05"/>
  </inertial>
  <visual>
    <origin rpy="0 0 0" xyz="-0.071147 -0.115794 -0.041"/>
    <geometry>
      <mesh filename="package://nightmare_description/meshes/leg_4_coxa_1.stl" scale="0.001 0.001 0.001"/>
    </geometry>
    <material name="silver">
      <color rgba="1 0 0 1"/>
    </material>
  </visual>
  <collision>
    <origin rpy="0 0 0" xyz="-0.071147 -0.115794 -0.041"/>
    <geometry>
      <mesh filename="package://nightmare_description/meshes/leg_4_coxa_1.stl" scale="0.001 0.001 0.001"/>
    </geometry>
  </collision>
</link>
<link name="leg_3_coxa_1">
  <inertial>
    <origin rpy="0 0 0" xyz="0.033498 0.0059070000000000025 -0.0205"/>
    <mass value="0.073783"/>
    <inertia ixx="3e-05" ixy="-1e-06" ixz="0.000146" iyy="3.5e-05" iyz="-0.000146" izz="3.5e-05"/>
  </inertial>
  <visual>
    <origin rpy="0 0 0" xyz="-0.108679 -0.039421 -0.041"/>
    <geometry>
      <mesh filename="package://nightmare_description/meshes/leg_3_coxa_1.stl" scale="0.001 0.001 0.001"/>
    </geometry>
    <material name="silver">
      <color rgba="1 0 0 1"/>
    </material>
  </visual>
  <collision>
    <origin rpy="0 0 0" xyz="-0.108679 -0.039421 -0.041"/>
    <geometry>
      <mesh filename="package://nightmare_description/meshes/leg_3_coxa_1.stl" scale="0.001 0.001 0.001"/>
    </geometry>
  </collision>
</link>
<link name="leg_2_coxa_1">
  <inertial>
    <origin rpy="0 0 0" xyz="0.033498 -0.0059070000000000025 -0.0205"/>
    <mass value="0.073783"/>
    <inertia ixx="3e-05" ixy="1e-06" ixz="0.000284" iyy="3.5e-05" iyz="-0.000284" izz="3.5e-05"/>
  </inertial>
  <visual>
    <origin rpy="0 0 0" xyz="-0.108679 0.039421 -0.041"/>
    <geometry>
      <mesh filename="package://nightmare_description/meshes/leg_2_coxa_1.stl" scale="0.001 0.001 0.001"/>
    </geometry>
    <material name="silver">
      <color rgba="1 0 0 1"/>
    </material>
  </visual>
  <collision>
    <origin rpy="0 0 0" xyz="-0.108679 0.039421 -0.041"/>
    <geometry>
      <mesh filename="package://nightmare_description/meshes/leg_2_coxa_1.stl" scale="0.001 0.001 0.001"/>
    </geometry>
  </collision>
</link>
<link name="leg_8_motor__1__1">
  <inertial>
    <origin rpy="0 0 0" xyz="-0.023161 0.006152999999999992 0.0"/>
    <mass value="0.315076"/>
    <inertia ixx="6e-05" ixy="-9e-06" ixz="0.000286" iyy="6e-05" iyz="-0.000286" izz="8.8e-05"/>
  </inertial>
  <visual>
    <origin rpy="0 0 0" xyz="0.101928 0.175566 -0.0205"/>
    <geometry>
      <mesh filename="package://nightmare_description/meshes/leg_8_motor__1__1.stl" scale="0.001 0.001 0.001"/>
    </geometry>
    <material name="silver">
      <color rgba="1 0 0 1"/>
    </material>
  </visual>
  <collision>
    <origin rpy="0 0 0" xyz="0.101928 0.175566 -0.0205"/>
    <geometry>
      <mesh filename="package://nightmare_description/meshes/leg_8_motor__1__1.stl" scale="0.001 0.001 0.001"/>
    </geometry>
  </collision>
</link>
<link name="leg_7_motor__1__1">
  <inertial>
    <origin rpy="0 0 0" xyz="-0.015443000000000012 0.018324 0.0"/>
    <mass value="0.315076"/>
    <inertia ixx="5.2e-05" ixy="-3e-06" ixz="-0.000868" iyy="6.9e-05" iyz="0.000868" izz="8.8e-05"/>
  </inertial>
  <visual>
    <origin rpy="0 0 0" xyz="0.172116 0.071423 -0.0205"/>
    <geometry>
      <mesh filename="package://nightmare_description/meshes/leg_7_motor__1__1.stl" scale="0.001 0.001 0.001"/>
    </geometry>
    <material name="silver">
      <color rgba="1 0 0 1"/>
    </material>
  </visual>
  <collision>
    <origin rpy="0 0 0" xyz="0.172116 0.071423 -0.0205"/>
    <geometry>
      <mesh filename="package://nightmare_description/meshes/leg_7_motor__1__1.stl" scale="0.001 0.001 0.001"/>
    </geometry>
  </collision>
</link>
<link name="leg_6_motor__1__1">
  <inertial>
    <origin rpy="0 0 0" xyz="-0.008244000000000001 0.022500999999999997 0.0"/>
    <mass value="0.315076"/>
    <inertia ixx="5.2e-05" ixy="3e-06" ixz="-0.001557" iyy="6.8e-05" iyz="0.001557" izz="8.8e-05"/>
  </inertial>
  <visual>
    <origin rpy="0 0 0" xyz="0.179236 -0.031046 -0.0205"/>
    <geometry>
      <mesh filename="package://nightmare_description/meshes/leg_6_motor__1__1.stl" scale="0.001 0.001 0.001"/>
    </geometry>
    <material name="silver">
      <color rgba="1 0 0 1"/>
    </material>
  </visual>
  <collision>
    <origin rpy="0 0 0" xyz="0.179236 -0.031046 -0.0205"/>
    <geometry>
      <mesh filename="package://nightmare_description/meshes/leg_6_motor__1__1.stl" scale="0.001 0.001 0.001"/>
    </geometry>
  </collision>
</link>
<link name="leg_5_motor__1__1">
  <inertial>
    <origin rpy="0 0 0" xyz="0.0061530000000000196 0.023159999999999986 0.0"/>
    <mass value="0.315076"/>
    <inertia ixx="6e-05" ixy="9e-06" ixz="-0.001939" iyy="6e-05" iyz="0.001939" izz="8.9e-05"/>
  </inertial>
  <visual>
    <origin rpy="0 0 0" xyz="0.133748 -0.149403 -0.0205"/>
    <geometry>
      <mesh filename="package://nightmare_description/meshes/leg_5_motor__1__1.stl" scale="0.001 0.001 0.001"/>
    </geometry>
    <material name="silver">
      <color rgba="1 0 0 1"/>
    </material>
  </visual>
  <collision>
    <origin rpy="0 0 0" xyz="0.133748 -0.149403 -0.0205"/>
    <geometry>
      <mesh filename="package://nightmare_description/meshes/leg_5_motor__1__1.stl" scale="0.001 0.001 0.001"/>
    </geometry>
  </collision>
</link>
<link name="leg_1_motor__1__1">
  <inertial>
    <origin rpy="0 0 0" xyz="0.022837999999999983 0.005831000000000003 0.0"/>
    <mass value="0.315076"/>
    <inertia ixx="6e-05" ixy="9e-06" ixz="0.001939" iyy="6e-05" iyz="-0.001939" izz="8.9e-05"/>
  </inertial>
  <visual>
    <origin rpy="0 0 0" xyz="-0.104757 0.178394 -0.0205"/>
    <geometry>
      <mesh filename="package://nightmare_description/meshes/leg_1_motor__1__1.stl" scale="0.001 0.001 0.001"/>
    </geometry>
    <material name="silver">
      <color rgba="1 0 0 1"/>
    </material>
  </visual>
  <collision>
    <origin rpy="0 0 0" xyz="-0.104757 0.178394 -0.0205"/>
    <geometry>
      <mesh filename="package://nightmare_description/meshes/leg_1_motor__1__1.stl" scale="0.001 0.001 0.001"/>
    </geometry>
  </collision>
</link>
<link name="leg_2_motor__1__1">
  <inertial>
    <origin rpy="0 0 0" xyz="0.015364000000000017 0.017876000000000003 0.0"/>
    <mass value="0.315076"/>
    <inertia ixx="5.2e-05" ixy="3e-06" ixz="0.001557" iyy="6.8e-05" iyz="-0.001557" izz="8.8e-05"/>
  </inertial>
  <visual>
    <origin rpy="0 0 0" xyz="-0.172116 0.071423 -0.0205"/>
    <geometry>
      <mesh filename="package://nightmare_description/meshes/leg_2_motor__1__1.stl" scale="0.001 0.001 0.001"/>
    </geometry>
    <material name="silver">
      <color rgba="1 0 0 1"/>
    </material>
  </visual>
  <collision>
    <origin rpy="0 0 0" xyz="-0.172116 0.071423 -0.0205"/>
    <geometry>
      <mesh filename="package://nightmare_description/meshes/leg_2_motor__1__1.stl" scale="0.001 0.001 0.001"/>
    </geometry>
  </collision>
</link>
<link name="leg_3_motor__1__1">
  <inertial>
    <origin rpy="0 0 0" xyz="0.008322999999999997 0.022053 0.0"/>
    <mass value="0.315076"/>
    <inertia ixx="5.2e-05" ixy="-3e-06" ixz="0.000868" iyy="6.9e-05" iyz="-0.000868" izz="8.8e-05"/>
  </inertial>
  <visual>
    <origin rpy="0 0 0" xyz="-0.179236 -0.031046 -0.0205"/>
    <geometry>
      <mesh filename="package://nightmare_description/meshes/leg_3_motor__1__1.stl" scale="0.001 0.001 0.001"/>
    </geometry>
    <material name="silver">
      <color rgba="1 0 0 1"/>
    </material>
  </visual>
  <collision>
    <origin rpy="0 0 0" xyz="-0.179236 -0.031046 -0.0205"/>
    <geometry>
      <mesh filename="package://nightmare_description/meshes/leg_3_motor__1__1.stl" scale="0.001 0.001 0.001"/>
    </geometry>
  </collision>
</link>
<link name="leg_4_motor__1__1">
  <inertial>
    <origin rpy="0 0 0" xyz="-0.005831000000000003 0.022838999999999998 0.0"/>
    <mass value="0.315076"/>
    <inertia ixx="6e-05" ixy="-9e-06" ixz="-0.000286" iyy="6e-05" iyz="0.000286" izz="8.8e-05"/>
  </inertial>
  <visual>
    <origin rpy="0 0 0" xyz="-0.133748 -0.149403 -0.0205"/>
    <geometry>
      <mesh filename="package://nightmare_description/meshes/leg_4_motor__1__1.stl" scale="0.001 0.001 0.001"/>
    </geometry>
    <material name="silver">
      <color rgba="1 0 0 1"/>
    </material>
  </visual>
  <collision>
    <origin rpy="0 0 0" xyz="-0.133748 -0.149403 -0.0205"/>
    <geometry>
      <mesh filename="package://nightmare_description/meshes/leg_4_motor__1__1.stl" scale="0.001 0.001 0.001"/>
    </geometry>
  </collision>
</link>
<link name="leg_1_femur_1">
  <inertial>
    <origin rpy="0 0 0" xyz="0.017868000000000023 -0.04230300000000001 -0.010633"/>
    <mass value="0.077868"/>
    <inertia ixx="4.3e-05" ixy="2.4e-05" ixz="0.000618" iyy="4.5e-05" iyz="-0.000618" izz="8.3e-05"/>
  </inertial>
  <visual>
    <origin rpy="0 0 0" xyz="-0.154961 0.174859 -0.031"/>
    <geometry>
      <mesh filename="package://nightmare_description/meshes/leg_1_femur_1.stl" scale="0.001 0.001 0.001"/>
    </geometry>
    <material name="silver">
      <color rgba="1 0 0 1"/>
    </material>
  </visual>
  <collision>
    <origin rpy="0 0 0" xyz="-0.154961 0.174859 -0.031"/>
    <geometry>
      <mesh filename="package://nightmare_description/meshes/leg_1_femur_1.stl" scale="0.001 0.001 0.001"/>
    </geometry>
  </collision>
</link>
<link name="leg_2_femur_1">
  <inertial>
    <origin rpy="0 0 0" xyz="0.03889999999999999 -0.024403999999999995 -0.010633"/>
    <mass value="0.077868"/>
    <inertia ixx="2.1e-05" ixy="7e-06" ixz="0.000498" iyy="6.7e-05" iyz="-0.000498" izz="8.3e-05"/>
  </inertial>
  <visual>
    <origin rpy="0 0 0" xyz="-0.211214 0.039731 -0.031"/>
    <geometry>
      <mesh filename="package://nightmare_description/meshes/leg_2_femur_1.stl" scale="0.001 0.001 0.001"/>
    </geometry>
    <material name="silver">
      <color rgba="1 0 0 1"/>
    </material>
  </visual>
  <collision>
    <origin rpy="0 0 0" xyz="-0.211214 0.039731 -0.031"/>
    <geometry>
      <mesh filename="package://nightmare_description/meshes/leg_2_femur_1.stl" scale="0.001 0.001 0.001"/>
    </geometry>
  </collision>
</link>
<link name="leg_3_femur_1">
  <inertial>
    <origin rpy="0 0 0" xyz="0.04490199999999997 -0.009626999999999997 -0.010633"/>
    <mass value="0.077868"/>
    <inertia ixx="2.2e-05" ixy="-9e-06" ixz="0.000294" iyy="6.7e-05" iyz="-0.000294" izz="8.3e-05"/>
  </inertial>
  <visual>
    <origin rpy="0 0 0" xyz="-0.205136 -0.074199 -0.031"/>
    <geometry>
      <mesh filename="package://nightmare_description/meshes/leg_3_femur_1.stl" scale="0.001 0.001 0.001"/>
    </geometry>
    <material name="silver">
      <color rgba="1 0 0 1"/>
    </material>
  </visual>
  <collision>
    <origin rpy="0 0 0" xyz="-0.205136 -0.074199 -0.031"/>
    <geometry>
      <mesh filename="package://nightmare_description/meshes/leg_3_femur_1.stl" scale="0.001 0.001 0.001"/>
    </geometry>
  </collision>
</link>
<link name="leg_4_femur_1">
  <inertial>
    <origin rpy="0 0 0" xyz="0.04230300000000001 0.017867999999999995 -0.010633"/>
    <mass value="0.077868"/>
    <inertia ixx="4.5e-05" ixy="-2.4e-05" ixz="-7.1e-05" iyy="4.3e-05" iyz="7.1e-05" izz="8.3e-05"/>
  </inertial>
  <visual>
    <origin rpy="0 0 0" xyz="-0.130213 -0.199608 -0.031"/>
    <geometry>
      <mesh filename="package://nightmare_description/meshes/leg_4_femur_1.stl" scale="0.001 0.001 0.001"/>
    </geometry>
    <material name="silver">
      <color rgba="1 0 0 1"/>
    </material>
  </visual>
  <collision>
    <origin rpy="0 0 0" xyz="-0.130213 -0.199608 -0.031"/>
    <geometry>
      <mesh filename="package://nightmare_description/meshes/leg_4_femur_1.stl" scale="0.001 0.001 0.001"/>
    </geometry>
  </collision>
</link>
<link name="leg_8_femur_1">
  <inertial>
    <origin rpy="0 0 0" xyz="-0.04230400000000001 -0.017867999999999995 -0.010633"/>
    <mass value="0.077868"/>
    <inertia ixx="4.5e-05" ixy="-2.4e-05" ixz="7.1e-05" iyy="4.3e-05" iyz="-7.1e-05" izz="8.3e-05"/>
  </inertial>
  <visual>
    <origin rpy="0 0 0" xyz="0.127384 0.196779 -0.031"/>
    <geometry>
      <mesh filename="package://nightmare_description/meshes/leg_8_femur_1.stl" scale="0.001 0.001 0.001"/>
    </geometry>
    <material name="silver">
      <color rgba="1 0 0 1"/>
    </material>
  </visual>
  <collision>
    <origin rpy="0 0 0" xyz="0.127384 0.196779 -0.031"/>
    <geometry>
      <mesh filename="package://nightmare_description/meshes/leg_8_femur_1.stl" scale="0.001 0.001 0.001"/>
    </geometry>
  </collision>
</link>
<link name="leg_6_femur_1">
  <inertial>
    <origin rpy="0 0 0" xyz="-0.03889999999999999 0.024403999999999995 -0.010633"/>
    <mass value="0.077868"/>
    <inertia ixx="2.1e-05" ixy="7e-06" ixz="-0.000498" iyy="6.7e-05" iyz="0.000498" izz="8.3e-05"/>
  </inertial>
  <visual>
    <origin rpy="0 0 0" xyz="0.211214 -0.039731 -0.031"/>
    <geometry>
      <mesh filename="package://nightmare_description/meshes/leg_6_femur_1.stl" scale="0.001 0.001 0.001"/>
    </geometry>
    <material name="silver">
      <color rgba="1 0 0 1"/>
    </material>
  </visual>
  <collision>
    <origin rpy="0 0 0" xyz="0.211214 -0.039731 -0.031"/>
    <geometry>
      <mesh filename="package://nightmare_description/meshes/leg_6_femur_1.stl" scale="0.001 0.001 0.001"/>
    </geometry>
  </collision>
</link>
<link name="leg_5_femur_1">
  <inertial>
    <origin rpy="0 0 0" xyz="-0.017868000000000023 0.04230300000000001 -0.010633"/>
    <mass value="0.077868"/>
    <inertia ixx="4.3e-05" ixy="2.4e-05" ixz="-0.000618" iyy="4.5e-05" iyz="0.000618" izz="8.3e-05"/>
  </inertial>
  <visual>
    <origin rpy="0 0 0" xyz="0.154961 -0.174859 -0.031"/>
    <geometry>
      <mesh filename="package://nightmare_description/meshes/leg_5_femur_1.stl" scale="0.001 0.001 0.001"/>
    </geometry>
    <material name="silver">
      <color rgba="1 0 0 1"/>
    </material>
  </visual>
  <collision>
    <origin rpy="0 0 0" xyz="0.154961 -0.174859 -0.031"/>
    <geometry>
      <mesh filename="package://nightmare_description/meshes/leg_5_femur_1.stl" scale="0.001 0.001 0.001"/>
    </geometry>
  </collision>
</link>
<link name="leg_1_motor__2__1">
  <inertial>
    <origin rpy="0 0 0" xyz="0.022838999999999998 0.005830999999999975 0.0"/>
    <mass value="0.315076"/>
    <inertia ixx="6e-05" ixy="9e-06" ixz="0.003044" iyy="6e-05" iyz="-0.003044" izz="8.8e-05"/>
  </inertial>
  <visual>
    <origin rpy="0 0 0" xyz="-0.192724 0.265655 -0.020321"/>
    <geometry>
      <mesh filename="package://nightmare_description/meshes/leg_1_motor__2__1.stl" scale="0.001 0.001 0.001"/>
    </geometry>
    <material name="silver">
      <color rgba="1 0 0 1"/>
    </material>
  </visual>
  <collision>
    <origin rpy="0 0 0" xyz="-0.192724 0.265655 -0.020321"/>
    <geometry>
      <mesh filename="package://nightmare_description/meshes/leg_1_motor__2__1.stl" scale="0.001 0.001 0.001"/>
    </geometry>
  </collision>
</link>
<link name="leg_2_motor__2__1">
  <inertial>
    <origin rpy="0 0 0" xyz="0.015363000000000016 0.017876000000000003 0.0"/>
    <mass value="0.315076"/>
    <inertia ixx="5.2e-05" ixy="3e-06" ixz="0.00246" iyy="6.8e-05" iyz="-0.00246" izz="8.8e-05"/>
  </inertial>
  <visual>
    <origin rpy="0 0 0" xyz="-0.294226 0.092447 -0.020321"/>
    <geometry>
      <mesh filename="package://nightmare_description/meshes/leg_2_motor__2__1.stl" scale="0.001 0.001 0.001"/>
    </geometry>
    <material name="silver">
      <color rgba="1 0 0 1"/>
    </material>
  </visual>
  <collision>
    <origin rpy="0 0 0" xyz="-0.294226 0.092447 -0.020321"/>
    <geometry>
      <mesh filename="package://nightmare_description/meshes/leg_2_motor__2__1.stl" scale="0.001 0.001 0.001"/>
    </geometry>
  </collision>
</link>
<link name="leg_3_motor__2__1">
  <inertial>
    <origin rpy="0 0 0" xyz="0.008323999999999998 0.022052999999999996 0.0"/>
    <mass value="0.315076"/>
    <inertia ixx="5.2e-05" ixy="-3e-06" ixz="0.001501" iyy="6.8e-05" iyz="-0.001501" izz="8.8e-05"/>
  </inertial>
  <visual>
    <origin rpy="0 0 0" xyz="-0.301171 -0.053054 -0.020321"/>
    <geometry>
      <mesh filename="package://nightmare_description/meshes/leg_3_motor__2__1.stl" scale="0.001 0.001 0.001"/>
    </geometry>
    <material name="silver">
      <color rgba="1 0 0 1"/>
    </material>
  </visual>
  <collision>
    <origin rpy="0 0 0" xyz="-0.301171 -0.053054 -0.020321"/>
    <geometry>
      <mesh filename="package://nightmare_description/meshes/leg_3_motor__2__1.stl" scale="0.001 0.001 0.001"/>
    </geometry>
  </collision>
</link>
<link name="leg_4_motor__2__1">
  <inertial>
    <origin rpy="0 0 0" xyz="-0.005831000000000003 0.022838000000000025 0.0"/>
    <mass value="0.315076"/>
    <inertia ixx="6e-05" ixy="-9e-06" ixz="-0.000288" iyy="6e-05" iyz="0.000288" izz="8.9e-05"/>
  </inertial>
  <visual>
    <origin rpy="0 0 0" xyz="-0.221008 -0.237371 -0.020321"/>
    <geometry>
      <mesh filename="package://nightmare_description/meshes/leg_4_motor__2__1.stl" scale="0.001 0.001 0.001"/>
    </geometry>
    <material name="silver">
      <color rgba="1 0 0 1"/>
    </material>
  </visual>
  <collision>
    <origin rpy="0 0 0" xyz="-0.221008 -0.237371 -0.020321"/>
    <geometry>
      <mesh filename="package://nightmare_description/meshes/leg_4_motor__2__1.stl" scale="0.001 0.001 0.001"/>
    </geometry>
  </collision>
</link>
<link name="leg_5_motor__2__1">
  <inertial>
    <origin rpy="0 0 0" xyz="0.006152999999999992 0.023159999999999986 0.0"/>
    <mass value="0.315076"/>
    <inertia ixx="6e-05" ixy="9e-06" ixz="-0.003044" iyy="6e-05" iyz="0.003044" izz="8.8e-05"/>
  </inertial>
  <visual>
    <origin rpy="0 0 0" xyz="0.221716 -0.236664 -0.020321"/>
    <geometry>
      <mesh filename="package://nightmare_description/meshes/leg_5_motor__2__1.stl" scale="0.001 0.001 0.001"/>
    </geometry>
    <material name="silver">
      <color rgba="1 0 0 1"/>
    </material>
  </visual>
  <collision>
    <origin rpy="0 0 0" xyz="0.221716 -0.236664 -0.020321"/>
    <geometry>
      <mesh filename="package://nightmare_description/meshes/leg_5_motor__2__1.stl" scale="0.001 0.001 0.001"/>
    </geometry>
  </collision>
</link>
<link name="leg_6_motor__2__1">
  <inertial>
    <origin rpy="0 0 0" xyz="-0.008244000000000029 0.022501 0.0"/>
    <mass value="0.315076"/>
    <inertia ixx="5.2e-05" ixy="3e-06" ixz="-0.00246" iyy="6.8e-05" iyz="0.00246" izz="8.8e-05"/>
  </inertial>
  <visual>
    <origin rpy="0 0 0" xyz="0.301345 -0.05207 -0.020321"/>
    <geometry>
      <mesh filename="package://nightmare_description/meshes/leg_6_motor__2__1.stl" scale="0.001 0.001 0.001"/>
    </geometry>
    <material name="silver">
      <color rgba="1 0 0 1"/>
    </material>
  </visual>
  <collision>
    <origin rpy="0 0 0" xyz="0.301345 -0.05207 -0.020321"/>
    <geometry>
      <mesh filename="package://nightmare_description/meshes/leg_6_motor__2__1.stl" scale="0.001 0.001 0.001"/>
    </geometry>
  </collision>
</link>
<link name="leg_7_motor__2__1">
  <inertial>
    <origin rpy="0 0 0" xyz="-0.01544300000000004 0.018325000000000008 0.0"/>
    <mass value="0.315076"/>
    <inertia ixx="5.2e-05" ixy="-3e-06" ixz="-0.001501" iyy="6.8e-05" iyz="0.001501" izz="8.8e-05"/>
  </inertial>
  <visual>
    <origin rpy="0 0 0" xyz="0.294052 0.093432 -0.020321"/>
    <geometry>
      <mesh filename="package://nightmare_description/meshes/leg_7_motor__2__1.stl" scale="0.001 0.001 0.001"/>
    </geometry>
    <material name="silver">
      <color rgba="1 0 0 1"/>
    </material>
  </visual>
  <collision>
    <origin rpy="0 0 0" xyz="0.294052 0.093432 -0.020321"/>
    <geometry>
      <mesh filename="package://nightmare_description/meshes/leg_7_motor__2__1.stl" scale="0.001 0.001 0.001"/>
    </geometry>
  </collision>
</link>
<link name="leg_8_motor__2__1">
  <inertial>
    <origin rpy="0 0 0" xyz="-0.023160000000000014 0.006152999999999964 0.0"/>
    <mass value="0.315076"/>
    <inertia ixx="6e-05" ixy="-9e-06" ixz="0.000288" iyy="6e-05" iyz="-0.000288" izz="8.8e-05"/>
  </inertial>
  <visual>
    <origin rpy="0 0 0" xyz="0.189189 0.263534 -0.020321"/>
    <geometry>
      <mesh filename="package://nightmare_description/meshes/leg_8_motor__2__1.stl" scale="0.001 0.001 0.001"/>
    </geometry>
    <material name="silver">
      <color rgba="1 0 0 1"/>
    </material>
  </visual>
  <collision>
    <origin rpy="0 0 0" xyz="0.189189 0.263534 -0.020321"/>
    <geometry>
      <mesh filename="package://nightmare_description/meshes/leg_8_motor__2__1.stl" scale="0.001 0.001 0.001"/>
    </geometry>
  </collision>
</link>
<link name="leg_8_tibia_1">
  <inertial>
    <origin rpy="0 0 0" xyz="-0.06303600000000001 -0.03870700000000005 -0.010864000000000002"/>
    <mass value="0.106884"/>
    <inertia ixx="0.000121" ixy="-0.000111" ixz="9.7e-05" iyy="0.000118" iyz="-9.8e-05" izz="0.000233"/>
  </inertial>
  <visual>
    <origin rpy="0 0 0" xyz="0.214645 0.284747 -0.030821"/>
    <geometry>
      <mesh filename="package://nightmare_description/meshes/leg_8_tibia_1.stl" scale="0.001 0.001 0.001"/>
    </geometry>
    <material name="silver">
      <color rgba="1 0 0 1"/>
    </material>
  </visual>
  <collision>
    <origin rpy="0 0 0" xyz="0.214645 0.284747 -0.030821"/>
    <geometry>
      <mesh filename="package://nightmare_description/meshes/leg_8_tibia_1.stl" scale="0.001 0.001 0.001"/>
    </geometry>
  </collision>
</link>
<link name="leg_6_tibia_1">
  <inertial>
    <origin rpy="0 0 0" xyz="-0.067863 0.029435000000000003 -0.010864000000000002"/>
    <mass value="0.106884"/>
    <inertia ixx="1.5e-05" ixy="3.6e-05" ixz="-0.001048" iyy="0.000224" iyz="0.001048" izz="0.000233"/>
  </inertial>
  <visual>
    <origin rpy="0 0 0" xyz="0.333323 -0.060754 -0.030821"/>
    <geometry>
      <mesh filename="package://nightmare_description/meshes/leg_6_tibia_1.stl" scale="0.001 0.001 0.001"/>
    </geometry>
    <material name="silver">
      <color rgba="1 0 0 1"/>
    </material>
  </visual>
  <collision>
    <origin rpy="0 0 0" xyz="0.333323 -0.060754 -0.030821"/>
    <geometry>
      <mesh filename="package://nightmare_description/meshes/leg_6_tibia_1.stl" scale="0.001 0.001 0.001"/>
    </geometry>
  </collision>
</link>
<link name="leg_5_tibia_1">
  <inertial>
    <origin rpy="0 0 0" xyz="-0.03870699999999999 0.06303700000000001 -0.010864000000000002"/>
    <mass value="0.106884"/>
    <inertia ixx="0.000118" ixy="0.000111" ixz="-0.001294" iyy="0.000121" iyz="0.001294" izz="0.000233"/>
  </inertial>
  <visual>
    <origin rpy="0 0 0" xyz="0.242929 -0.262119 -0.030821"/>
    <geometry>
      <mesh filename="package://nightmare_description/meshes/leg_5_tibia_1.stl" scale="0.001 0.001 0.001"/>
    </geometry>
    <material name="silver">
      <color rgba="1 0 0 1"/>
    </material>
  </visual>
  <collision>
    <origin rpy="0 0 0" xyz="0.242929 -0.262119 -0.030821"/>
    <geometry>
      <mesh filename="package://nightmare_description/meshes/leg_5_tibia_1.stl" scale="0.001 0.001 0.001"/>
    </geometry>
  </collision>
</link>
<link name="leg_4_tibia_1">
  <inertial>
    <origin rpy="0 0 0" xyz="0.06303600000000001 0.038707999999999965 -0.010864000000000002"/>
    <mass value="0.106884"/>
    <inertia ixx="0.000121" ixy="-0.000111" ixz="-9.7e-05" iyy="0.000118" iyz="9.8e-05" izz="0.000233"/>
  </inertial>
  <visual>
    <origin rpy="0 0 0" xyz="-0.217473 -0.287575 -0.030821"/>
    <geometry>
      <mesh filename="package://nightmare_description/meshes/leg_4_tibia_1.stl" scale="0.001 0.001 0.001"/>
    </geometry>
    <material name="silver">
      <color rgba="1 0 0 1"/>
    </material>
  </visual>
  <collision>
    <origin rpy="0 0 0" xyz="-0.217473 -0.287575 -0.030821"/>
    <geometry>
      <mesh filename="package://nightmare_description/meshes/leg_4_tibia_1.stl" scale="0.001 0.001 0.001"/>
    </geometry>
  </collision>
</link>
<link name="leg_3_tibia_1">
  <inertial>
    <origin rpy="0 0 0" xyz="0.07383800000000001 -0.0044490000000000085 -0.010864000000000002"/>
    <mass value="0.106884"/>
    <inertia ixx="1.6e-05" ixy="-3.9e-05" ixz="0.00066" iyy="0.000223" iyz="-0.000659" izz="0.000233"/>
  </inertial>
  <visual>
    <origin rpy="0 0 0" xyz="-0.327072 -0.096208 -0.030821"/>
    <geometry>
      <mesh filename="package://nightmare_description/meshes/leg_3_tibia_1.stl" scale="0.001 0.001 0.001"/>
    </geometry>
    <material name="silver">
      <color rgba="1 0 0 1"/>
    </material>
  </visual>
  <collision>
    <origin rpy="0 0 0" xyz="-0.327072 -0.096208 -0.030821"/>
    <geometry>
      <mesh filename="package://nightmare_description/meshes/leg_3_tibia_1.stl" scale="0.001 0.001 0.001"/>
    </geometry>
  </collision>
</link>
<link name="leg_2_tibia_1">
  <inertial>
    <origin rpy="0 0 0" xyz="0.067863 -0.029435000000000003 -0.010864000000000002"/>
    <mass value="0.106884"/>
    <inertia ixx="1.5e-05" ixy="3.6e-05" ixz="0.001048" iyy="0.000224" iyz="-0.001048" izz="0.000233"/>
  </inertial>
  <visual>
    <origin rpy="0 0 0" xyz="-0.333323 0.060754 -0.030821"/>
    <geometry>
      <mesh filename="package://nightmare_description/meshes/leg_2_tibia_1.stl" scale="0.001 0.001 0.001"/>
    </geometry>
    <material name="silver">
      <color rgba="1 0 0 1"/>
    </material>
  </visual>
  <collision>
    <origin rpy="0 0 0" xyz="-0.333323 0.060754 -0.030821"/>
    <geometry>
      <mesh filename="package://nightmare_description/meshes/leg_2_tibia_1.stl" scale="0.001 0.001 0.001"/>
    </geometry>
  </collision>
</link>
<link name="leg_1_tibia_1">
  <inertial>
    <origin rpy="0 0 0" xyz="0.03870699999999999 -0.06303700000000001 -0.010864000000000002"/>
    <mass value="0.106884"/>
    <inertia ixx="0.000118" ixy="0.000111" ixz="0.001294" iyy="0.000121" iyz="-0.001294" izz="0.000233"/>
  </inertial>
  <visual>
    <origin rpy="0 0 0" xyz="-0.242929 0.262119 -0.030821"/>
    <geometry>
      <mesh filename="package://nightmare_description/meshes/leg_1_tibia_1.stl" scale="0.001 0.001 0.001"/>
    </geometry>
    <material name="silver">
      <color rgba="1 0 0 1"/>
    </material>
  </visual>
  <collision>
    <origin rpy="0 0 0" xyz="-0.242929 0.262119 -0.030821"/>
    <geometry>
      <mesh filename="package://nightmare_description/meshes/leg_1_tibia_1.stl" scale="0.001 0.001 0.001"/>
    </geometry>
  </collision>
</link>
<link name="Component62_1">
  <inertial>
    <origin rpy="0 0 0" xyz="6.400000000000001e-05 -0.083482 -0.020242000000000003"/>
    <mass value="0.502392"/>
    <inertia ixx="0.001514" ixy="0.0" ixz="0.002414" iyy="0.000379" iyz="-0.002422" izz="0.001285"/>
  </inertial>
  <visual>
    <origin rpy="0 0 0" xyz="0.00025 0.149 -0.041"/>
    <geometry>
      <mesh filename="package://nightmare_description/meshes/Component62_1.stl" scale="0.001 0.001 0.001"/>
    </geometry>
    <material name="silver">
      <color rgba="1 0 0 1"/>
    </material>
  </visual>
  <collision>
    <origin rpy="0 0 0" xyz="0.00025 0.149 -0.041"/>
    <geometry>
      <mesh filename="package://nightmare_description/meshes/Component62_1.stl" scale="0.001 0.001 0.001"/>
    </geometry>
  </collision>
</link>
<link name="head_neck_1">
  <inertial>
    <origin rpy="0 0 0" xyz="0.001783 0.03881100000000001 -0.019412000000000002"/>
    <mass value="0.21541"/>
    <inertia ixx="6.1e-05" ixy="-1e-06" ixz="-0.000865" iyy="6e-05" iyz="0.000864" izz="4.1e-05"/>
  </inertial>
  <visual>
    <origin rpy="0 0 0" xyz="-0.00025 -0.149 -0.041"/>
    <geometry>
      <mesh filename="package://nightmare_description/meshes/head_neck_1.stl" scale="0.001 0.001 0.001"/>
    </geometry>
    <material name="silver">
      <color rgba="1 0 0 1"/>
    </material>
  </visual>
  <collision>
    <origin rpy="0 0 0" xyz="-0.00025 -0.149 -0.041"/>
    <geometry>
      <mesh filename="package://nightmare_description/meshes/head_neck_1.stl" scale="0.001 0.001 0.001"/>
    </geometry>
  </collision>
</link>
<link name="leg_7_femur_1">
  <inertial>
    <origin rpy="0 0 0" xyz="-0.04490199999999997 0.009626999999999997 -0.010633"/>
    <mass value="0.077868"/>
    <inertia ixx="2.2e-05" ixy="-9e-06" ixz="-0.000294" iyy="6.7e-05" iyz="0.000294" izz="8.3e-05"/>
  </inertial>
  <visual>
    <origin rpy="0 0 0" xyz="0.205136 0.074199 -0.031"/>
    <geometry>
      <mesh filename="package://nightmare_description/meshes/leg_7_femur_1.stl" scale="0.001 0.001 0.001"/>
    </geometry>
    <material name="silver">
      <color rgba="1 0 0 1"/>
    </material>
  </visual>
  <collision>
    <origin rpy="0 0 0" xyz="0.205136 0.074199 -0.031"/>
    <geometry>
      <mesh filename="package://nightmare_description/meshes/leg_7_femur_1.stl" scale="0.001 0.001 0.001"/>
    </geometry>
  </collision>
</link>
<link name="leg_7_tibia_1">
  <inertial>
    <origin rpy="0 0 0" xyz="-0.07383899999999999 0.0044490000000000085 -0.010864000000000002"/>
    <mass value="0.106884"/>
    <inertia ixx="1.6e-05" ixy="-3.9e-05" ixz="-0.00066" iyy="0.000223" iyz="0.000659" izz="0.000233"/>
  </inertial>
  <visual>
    <origin rpy="0 0 0" xyz="0.327071 0.096208 -0.030821"/>
    <geometry>
      <mesh filename="package://nightmare_description/meshes/leg_7_tibia_1.stl" scale="0.001 0.001 0.001"/>
    </geometry>
    <material name="silver">
      <color rgba="1 0 0 1"/>
    </material>
  </visual>
  <collision>
    <origin rpy="0 0 0" xyz="0.327071 0.096208 -0.030821"/>
    <geometry>
      <mesh filename="package://nightmare_description/meshes/leg_7_tibia_1.stl" scale="0.001 0.001 0.001"/>
    </geometry>
  </collision>
</link>
<link name="head_link_1">
  <inertial>
    <origin rpy="0 0 0" xyz="0.025274 0.03397799999999998 0.0013080000000000001"/>
    <mass value="0.386958"/>
    <inertia ixx="5.3e-05" ixy="-1e-06" ixz="-0.00279" iyy="0.000245" iyz="0.002789" izz="0.000265"/>
  </inertial>
  <visual>
    <origin rpy="0 0 0" xyz="0.02475 -0.194 -0.030378"/>
    <geometry>
      <mesh filename="package://nightmare_description/meshes/head_link_1.stl" scale="0.001 0.001 0.001"/>
    </geometry>
    <material name="silver">
      <color rgba="1 0 0 1"/>
    </material>
  </visual>
  <collision>
    <origin rpy="0 0 0" xyz="0.02475 -0.194 -0.030378"/>
    <geometry>
      <mesh filename="package://nightmare_description/meshes/head_link_1.stl" scale="0.001 0.001 0.001"/>
    </geometry>
  </collision>
</link>
<joint name="Rigid14" type="fixed">
  <origin rpy="0 0 0" xyz="-0.039681 -0.099177 0.038"/>
  <parent link="base_link"/>
  <child link="leg_8_motor_1"/>
</joint>
<transmission name="Rigid14_tran">
  <type>transmission_interface/SimpleTransmission</type>
  <joint name="Rigid14">
    <hardwareInterface>PositionJointInterface</hardwareInterface>
  </joint>
  <actuator name="Rigid14_actr">
    <hardwareInterface>PositionJointInterface</hardwareInterface>
    <mechanicalReduction>1</mechanicalReduction>
  </actuator>
</transmission>
<joint name="Rigid15" type="fixed">
  <origin rpy="0 0 0" xyz="0.04251 -0.102005 0.038"/>
  <parent link="base_link"/>
  <child link="leg_1_motor_1"/>
</joint>
<transmission name="Rigid15_tran">
  <type>transmission_interface/SimpleTransmission</type>
  <joint name="Rigid15">
    <hardwareInterface>PositionJointInterface</hardwareInterface>
  </joint>
  <actuator name="Rigid15_actr">
    <hardwareInterface>PositionJointInterface</hardwareInterface>
    <mechanicalReduction>1</mechanicalReduction>
  </actuator>
</transmission>
<joint name="Rigid16" type="fixed">
  <origin rpy="0 0 0" xyz="0.01025 -0.119 0.038"/>
  <parent link="base_link"/>
  <child link="tail_motor_1"/>
</joint>
<transmission name="Rigid16_tran">
  <type>transmission_interface/SimpleTransmission</type>
  <joint name="Rigid16">
    <hardwareInterface>PositionJointInterface</hardwareInterface>
  </joint>
  <actuator name="Rigid16_actr">
    <hardwareInterface>PositionJointInterface</hardwareInterface>
    <mechanicalReduction>1</mechanicalReduction>
  </actuator>
</transmission>
<joint name="Rigid17" type="fixed">
  <origin rpy="0 0 0" xyz="0.077311 -0.044552 0.038"/>
  <parent link="base_link"/>
  <child link="leg_2_motor_1"/>
</joint>
<transmission name="Rigid17_tran">
  <type>transmission_interface/SimpleTransmission</type>
  <joint name="Rigid17">
    <hardwareInterface>PositionJointInterface</hardwareInterface>
  </joint>
  <actuator name="Rigid17_actr">
    <hardwareInterface>PositionJointInterface</hardwareInterface>
    <mechanicalReduction>1</mechanicalReduction>
  </actuator>
</transmission>
<joint name="Rigid18" type="fixed">
  <origin rpy="0 0 0" xyz="0.077311 0.044552 0.038"/>
  <parent link="base_link"/>
  <child link="leg_3_motor_1"/>
</joint>
<transmission name="Rigid18_tran">
  <type>transmission_interface/SimpleTransmission</type>
  <joint name="Rigid18">
    <hardwareInterface>PositionJointInterface</hardwareInterface>
  </joint>
  <actuator name="Rigid18_actr">
    <hardwareInterface>PositionJointInterface</hardwareInterface>
    <mechanicalReduction>1</mechanicalReduction>
  </actuator>
</transmission>
<joint name="Rigid19" type="fixed">
  <origin rpy="0 0 0" xyz="0.04251 0.102005 0.038"/>
  <parent link="base_link"/>
  <child link="leg_4_motor_1"/>
</joint>
<transmission name="Rigid19_tran">
  <type>transmission_interface/SimpleTransmission</type>
  <joint name="Rigid19">
    <hardwareInterface>PositionJointInterface</hardwareInterface>
  </joint>
  <actuator name="Rigid19_actr">
    <hardwareInterface>PositionJointInterface</hardwareInterface>
    <mechanicalReduction>1</mechanicalReduction>
  </actuator>
</transmission>
<joint name="Rigid20" type="fixed">
  <origin rpy="0 0 0" xyz="-0.01025 0.119 0.038"/>
  <parent link="base_link"/>
  <child link="head_motor_pan_1"/>
</joint>
<transmission name="Rigid20_tran">
  <type>transmission_interface/SimpleTransmission</type>
  <joint name="Rigid20">
    <hardwareInterface>PositionJointInterface</hardwareInterface>
  </joint>
  <actuator name="Rigid20_actr">
    <hardwareInterface>PositionJointInterface</hardwareInterface>
    <mechanicalReduction>1</mechanicalReduction>
  </actuator>
</transmission>
<joint name="Rigid21" type="fixed">
  <origin rpy="0 0 0" xyz="-0.04251 0.102005 0.038"/>
  <parent link="base_link"/>
  <child link="leg_5_motor_1"/>
</joint>
<transmission name="Rigid21_tran">
  <type>transmission_interface/SimpleTransmission</type>
  <joint name="Rigid21">
    <hardwareInterface>PositionJointInterface</hardwareInterface>
  </joint>
  <actuator name="Rigid21_actr">
    <hardwareInterface>PositionJointInterface</hardwareInterface>
    <mechanicalReduction>1</mechanicalReduction>
  </actuator>
</transmission>
<joint name="Rigid22" type="fixed">
  <origin rpy="0 0 0" xyz="-0.077311 0.044552 0.038"/>
  <parent link="base_link"/>
  <child link="leg_6_motor_1"/>
</joint>
<transmission name="Rigid22_tran">
  <type>transmission_interface/SimpleTransmission</type>
  <joint name="Rigid22">
    <hardwareInterface>PositionJointInterface</hardwareInterface>
  </joint>
  <actuator name="Rigid22_actr">
    <hardwareInterface>PositionJointInterface</hardwareInterface>
    <mechanicalReduction>1</mechanicalReduction>
  </actuator>
</transmission>
<joint name="Rigid23" type="fixed">
  <origin rpy="0 0 0" xyz="-0.077311 -0.044552 0.038"/>
  <parent link="base_link"/>
  <child link="leg_7_motor_1"/>
</joint>
<transmission name="Rigid23_tran">
  <type>transmission_interface/SimpleTransmission</type>
  <joint name="Rigid23">
    <hardwareInterface>PositionJointInterface</hardwareInterface>
  </joint>
  <actuator name="Rigid23_actr">
    <hardwareInterface>PositionJointInterface</hardwareInterface>
    <mechanicalReduction>1</mechanicalReduction>
  </actuator>
</transmission>
<joint name="Rev24" type="continuous">
  <origin rpy="0 0 0" xyz="0.028637 -0.013789 0.003"/>
  <parent link="leg_1_motor_1"/>
  <child link="leg_1_coxa_1"/>
  <axis xyz="-0.0 0.0 -0.01"/>
</joint>
<transmission name="Rev24_tran">
  <type>transmission_interface/SimpleTransmission</type>
  <joint name="Rev24">
    <hardwareInterface>PositionJointInterface</hardwareInterface>
  </joint>
  <actuator name="Rev24_actr">
    <hardwareInterface>PositionJointInterface</hardwareInterface>
    <mechanicalReduction>1</mechanicalReduction>
  </actuator>
</transmission>
<joint name="Rev25" type="continuous">
  <origin rpy="0 0 0" xyz="-0.028638 -0.013788 0.003"/>
  <parent link="leg_8_motor_1"/>
  <child link="leg_8_coxa_1"/>
  <axis xyz="-0.0 0.0 -0.01"/>
</joint>
<transmission name="Rev25_tran">
  <type>transmission_interface/SimpleTransmission</type>
  <joint name="Rev25">
    <hardwareInterface>PositionJointInterface</hardwareInterface>
  </joint>
  <actuator name="Rev25_actr">
    <hardwareInterface>PositionJointInterface</hardwareInterface>
    <mechanicalReduction>1</mechanicalReduction>
  </actuator>
</transmission>
<joint name="Rev26" type="continuous">
  <origin rpy="0 0 0" xyz="-0.031368 0.005131 0.003"/>
  <parent link="leg_7_motor_1"/>
  <child link="leg_7_coxa_1"/>
  <axis xyz="-0.0 0.0 -0.01"/>
</joint>
<transmission name="Rev26_tran">
  <type>transmission_interface/SimpleTransmission</type>
  <joint name="Rev26">
    <hardwareInterface>PositionJointInterface</hardwareInterface>
  </joint>
  <actuator name="Rev26_actr">
    <hardwareInterface>PositionJointInterface</hardwareInterface>
    <mechanicalReduction>1</mechanicalReduction>
  </actuator>
</transmission>
<joint name="Rev27" type="continuous">
  <origin rpy="0 0 0" xyz="-0.031368 -0.005131 0.003"/>
  <parent link="leg_6_motor_1"/>
  <child link="leg_6_coxa_1"/>
  <axis xyz="0.0 0.0 -0.01"/>
</joint>
<transmission name="Rev27_tran">
  <type>transmission_interface/SimpleTransmission</type>
  <joint name="Rev27">
    <hardwareInterface>PositionJointInterface</hardwareInterface>
  </joint>
  <actuator name="Rev27_actr">
    <hardwareInterface>PositionJointInterface</hardwareInterface>
    <mechanicalReduction>1</mechanicalReduction>
  </actuator>
</transmission>
<joint name="Rev28" type="continuous">
  <origin rpy="0 0 0" xyz="-0.028637 0.013789 0.003"/>
  <parent link="leg_5_motor_1"/>
  <child link="leg_5_coxa_1"/>
  <axis xyz="-0.0 0.0 -0.01"/>
</joint>
<transmission name="Rev28_tran">
  <type>transmission_interface/SimpleTransmission</type>
  <joint name="Rev28">
    <hardwareInterface>PositionJointInterface</hardwareInterface>
  </joint>
  <actuator name="Rev28_actr">
    <hardwareInterface>PositionJointInterface</hardwareInterface>
    <mechanicalReduction>1</mechanicalReduction>
  </actuator>
</transmission>
<joint name="Rev29" type="continuous">
  <origin rpy="0 0 0" xyz="0.028637 0.013789 0.003"/>
  <parent link="leg_4_motor_1"/>
  <child link="leg_4_coxa_1"/>
  <axis xyz="-0.0 0.0 -0.01"/>
</joint>
<transmission name="Rev29_tran">
  <type>transmission_interface/SimpleTransmission</type>
  <joint name="Rev29">
    <hardwareInterface>PositionJointInterface</hardwareInterface>
  </joint>
  <actuator name="Rev29_actr">
    <hardwareInterface>PositionJointInterface</hardwareInterface>
    <mechanicalReduction>1</mechanicalReduction>
  </actuator>
</transmission>
<joint name="Rev30" type="continuous">
  <origin rpy="0 0 0" xyz="0.031368 -0.005131 0.003"/>
  <parent link="leg_3_motor_1"/>
  <child link="leg_3_coxa_1"/>
  <axis xyz="-0.0 0.0 -0.01"/>
</joint>
<transmission name="Rev30_tran">
  <type>transmission_interface/SimpleTransmission</type>
  <joint name="Rev30">
    <hardwareInterface>PositionJointInterface</hardwareInterface>
  </joint>
  <actuator name="Rev30_actr">
    <hardwareInterface>PositionJointInterface</hardwareInterface>
    <mechanicalReduction>1</mechanicalReduction>
  </actuator>
</transmission>
<joint name="Rev31" type="continuous">
  <origin rpy="0 0 0" xyz="0.031368 0.005131 0.003"/>
  <parent link="leg_2_motor_1"/>
  <child link="leg_2_coxa_1"/>
  <axis xyz="-0.0 0.0 -0.01"/>
</joint>
<transmission name="Rev31_tran">
  <type>transmission_interface/SimpleTransmission</type>
  <joint name="Rev31">
    <hardwareInterface>PositionJointInterface</hardwareInterface>
  </joint>
  <actuator name="Rev31_actr">
    <hardwareInterface>PositionJointInterface</hardwareInterface>
    <mechanicalReduction>1</mechanicalReduction>
  </actuator>
</transmission>
<joint name="Rev32" type="continuous">
  <origin rpy="0 0 0" xyz="-0.033609 -0.062601 -0.0205"/>
  <parent link="leg_8_coxa_1"/>
  <child link="leg_8_motor__1__1"/>
  <axis xyz="-0.007071 0.007071 -0.0"/>
</joint>
<transmission name="Rev32_tran">
  <type>transmission_interface/SimpleTransmission</type>
  <joint name="Rev32">
    <hardwareInterface>PositionJointInterface</hardwareInterface>
  </joint>
  <actuator name="Rev32_actr">
    <hardwareInterface>PositionJointInterface</hardwareInterface>
    <mechanicalReduction>1</mechanicalReduction>
  </actuator>
</transmission>
<joint name="Rev33" type="continuous">
  <origin rpy="0 0 0" xyz="-0.063437 -0.032002 -0.0205"/>
  <parent link="leg_7_coxa_1"/>
  <child link="leg_7_motor__1__1"/>
  <axis xyz="-0.001736 0.009848 -0.0"/>
</joint>
<transmission name="Rev33_tran">
  <type>transmission_interface/SimpleTransmission</type>
  <joint name="Rev33">
    <hardwareInterface>PositionJointInterface</hardwareInterface>
  </joint>
  <actuator name="Rev33_actr">
    <hardwareInterface>PositionJointInterface</hardwareInterface>
    <mechanicalReduction>1</mechanicalReduction>
  </actuator>
</transmission>
<joint name="Rev34" type="continuous">
  <origin rpy="0 0 0" xyz="-0.070557 -0.008375 -0.0205"/>
  <parent link="leg_6_coxa_1"/>
  <child link="leg_6_motor__1__1"/>
  <axis xyz="0.001736 0.009848 -0.0"/>
</joint>
<transmission name="Rev34_tran">
  <type>transmission_interface/SimpleTransmission</type>
  <joint name="Rev34">
    <hardwareInterface>PositionJointInterface</hardwareInterface>
  </joint>
  <actuator name="Rev34_actr">
    <hardwareInterface>PositionJointInterface</hardwareInterface>
    <mechanicalReduction>1</mechanicalReduction>
  </actuator>
</transmission>
<joint name="Rev35" type="continuous">
  <origin rpy="0 0 0" xyz="-0.062601 0.033609 -0.0205"/>
  <parent link="leg_5_coxa_1"/>
  <child link="leg_5_motor__1__1"/>
  <axis xyz="0.007071 0.007071 -0.0"/>
</joint>
<transmission name="Rev35_tran">
  <type>transmission_interface/SimpleTransmission</type>
  <joint name="Rev35">
    <hardwareInterface>PositionJointInterface</hardwareInterface>
  </joint>
  <actuator name="Rev35_actr">
    <hardwareInterface>PositionJointInterface</hardwareInterface>
    <mechanicalReduction>1</mechanicalReduction>
  </actuator>
</transmission>
<joint name="Rev36" type="continuous">
  <origin rpy="0 0 0" xyz="0.03361 -0.0626 -0.0205"/>
  <parent link="leg_1_coxa_1"/>
  <child link="leg_1_motor__1__1"/>
  <axis xyz="-0.007071 -0.007071 -0.0"/>
</joint>
<transmission name="Rev36_tran">
  <type>transmission_interface/SimpleTransmission</type>
  <joint name="Rev36">
    <hardwareInterface>PositionJointInterface</hardwareInterface>
  </joint>
  <actuator name="Rev36_actr">
    <hardwareInterface>PositionJointInterface</hardwareInterface>
    <mechanicalReduction>1</mechanicalReduction>
  </actuator>
</transmission>
<joint name="Rev37" type="continuous">
  <origin rpy="0 0 0" xyz="0.063437 -0.032002 -0.0205"/>
  <parent link="leg_2_coxa_1"/>
  <child link="leg_2_motor__1__1"/>
  <axis xyz="-0.001736 -0.009848 -0.0"/>
</joint>
<transmission name="Rev37_tran">
  <type>transmission_interface/SimpleTransmission</type>
  <joint name="Rev37">
    <hardwareInterface>PositionJointInterface</hardwareInterface>
  </joint>
  <actuator name="Rev37_actr">
    <hardwareInterface>PositionJointInterface</hardwareInterface>
    <mechanicalReduction>1</mechanicalReduction>
  </actuator>
</transmission>
<joint name="Rev38" type="continuous">
  <origin rpy="0 0 0" xyz="0.070557 -0.008375 -0.0205"/>
  <parent link="leg_3_coxa_1"/>
  <child link="leg_3_motor__1__1"/>
  <axis xyz="0.001736 -0.009848 -0.0"/>
</joint>
<transmission name="Rev38_tran">
  <type>transmission_interface/SimpleTransmission</type>
  <joint name="Rev38">
    <hardwareInterface>PositionJointInterface</hardwareInterface>
  </joint>
  <actuator name="Rev38_actr">
    <hardwareInterface>PositionJointInterface</hardwareInterface>
    <mechanicalReduction>1</mechanicalReduction>
  </actuator>
</transmission>
<joint name="Rev39" type="continuous">
  <origin rpy="0 0 0" xyz="0.062601 0.033609 -0.0205"/>
  <parent link="leg_4_coxa_1"/>
  <child link="leg_4_motor__1__1"/>
  <axis xyz="0.007071 -0.007071 -0.0"/>
</joint>
<transmission name="Rev39_tran">
  <type>transmission_interface/SimpleTransmission</type>
  <joint name="Rev39">
    <hardwareInterface>PositionJointInterface</hardwareInterface>
  </joint>
  <actuator name="Rev39_actr">
    <hardwareInterface>PositionJointInterface</hardwareInterface>
    <mechanicalReduction>1</mechanicalReduction>
  </actuator>
</transmission>
<joint name="Rigid40" type="fixed">
  <origin rpy="0 0 0" xyz="0.050204 0.003535 0.0105"/>
  <parent link="leg_1_motor__1__1"/>
  <child link="leg_1_femur_1"/>
</joint>
<transmission name="Rigid40_tran">
  <type>transmission_interface/SimpleTransmission</type>
  <joint name="Rigid40">
    <hardwareInterface>PositionJointInterface</hardwareInterface>
  </joint>
  <actuator name="Rigid40_actr">
    <hardwareInterface>PositionJointInterface</hardwareInterface>
    <mechanicalReduction>1</mechanicalReduction>
  </actuator>
</transmission>
<joint name="Rigid41" type="fixed">
  <origin rpy="0 0 0" xyz="0.039098 0.031692 0.0105"/>
  <parent link="leg_2_motor__1__1"/>
  <child link="leg_2_femur_1"/>
</joint>
<transmission name="Rigid41_tran">
  <type>transmission_interface/SimpleTransmission</type>
  <joint name="Rigid41">
    <hardwareInterface>PositionJointInterface</hardwareInterface>
  </joint>
  <actuator name="Rigid41_actr">
    <hardwareInterface>PositionJointInterface</hardwareInterface>
    <mechanicalReduction>1</mechanicalReduction>
  </actuator>
</transmission>
<joint name="Rigid42" type="fixed">
  <origin rpy="0 0 0" xyz="0.0259 0.043153 0.0105"/>
  <parent link="leg_3_motor__1__1"/>
  <child link="leg_3_femur_1"/>
</joint>
<transmission name="Rigid42_tran">
  <type>transmission_interface/SimpleTransmission</type>
  <joint name="Rigid42">
    <hardwareInterface>PositionJointInterface</hardwareInterface>
  </joint>
  <actuator name="Rigid42_actr">
    <hardwareInterface>PositionJointInterface</hardwareInterface>
    <mechanicalReduction>1</mechanicalReduction>
  </actuator>
</transmission>
<joint name="Rigid43" type="fixed">
  <origin rpy="0 0 0" xyz="-0.003535 0.050205 0.0105"/>
  <parent link="leg_4_motor__1__1"/>
  <child link="leg_4_femur_1"/>
</joint>
<transmission name="Rigid43_tran">
  <type>transmission_interface/SimpleTransmission</type>
  <joint name="Rigid43">
    <hardwareInterface>PositionJointInterface</hardwareInterface>
  </joint>
  <actuator name="Rigid43_actr">
    <hardwareInterface>PositionJointInterface</hardwareInterface>
    <mechanicalReduction>1</mechanicalReduction>
  </actuator>
</transmission>
<joint name="Rigid44" type="fixed">
  <origin rpy="0 0 0" xyz="-0.025456 -0.021213 0.0105"/>
  <parent link="leg_8_motor__1__1"/>
  <child link="leg_8_femur_1"/>
</joint>
<transmission name="Rigid44_tran">
  <type>transmission_interface/SimpleTransmission</type>
  <joint name="Rigid44">
    <hardwareInterface>PositionJointInterface</hardwareInterface>
  </joint>
  <actuator name="Rigid44_actr">
    <hardwareInterface>PositionJointInterface</hardwareInterface>
    <mechanicalReduction>1</mechanicalReduction>
  </actuator>
</transmission>
<joint name="Rigid46" type="fixed">
  <origin rpy="0 0 0" xyz="-0.031978 0.008685 0.0105"/>
  <parent link="leg_6_motor__1__1"/>
  <child link="leg_6_femur_1"/>
</joint>
<transmission name="Rigid46_tran">
  <type>transmission_interface/SimpleTransmission</type>
  <joint name="Rigid46">
    <hardwareInterface>PositionJointInterface</hardwareInterface>
  </joint>
  <actuator name="Rigid46_actr">
    <hardwareInterface>PositionJointInterface</hardwareInterface>
    <mechanicalReduction>1</mechanicalReduction>
  </actuator>
</transmission>
<joint name="Rigid47" type="fixed">
  <origin rpy="0 0 0" xyz="-0.021213 0.025456 0.0105"/>
  <parent link="leg_5_motor__1__1"/>
  <child link="leg_5_femur_1"/>
</joint>
<transmission name="Rigid47_tran">
  <type>transmission_interface/SimpleTransmission</type>
  <joint name="Rigid47">
    <hardwareInterface>PositionJointInterface</hardwareInterface>
  </joint>
  <actuator name="Rigid47_actr">
    <hardwareInterface>PositionJointInterface</hardwareInterface>
    <mechanicalReduction>1</mechanicalReduction>
  </actuator>
</transmission>
<joint name="Rev48" type="continuous">
  <origin rpy="0 0 0" xyz="0.037763 -0.090796 -0.010679"/>
  <parent link="leg_1_femur_1"/>
  <child link="leg_1_motor__2__1"/>
  <axis xyz="-0.007071 -0.007071 -0.0"/>
</joint>
<transmission name="Rev48_tran">
  <type>transmission_interface/SimpleTransmission</type>
  <joint name="Rev48">
    <hardwareInterface>PositionJointInterface</hardwareInterface>
  </joint>
  <actuator name="Rev48_actr">
    <hardwareInterface>PositionJointInterface</hardwareInterface>
    <mechanicalReduction>1</mechanicalReduction>
  </actuator>
</transmission>
<joint name="Rev49" type="continuous">
  <origin rpy="0 0 0" xyz="0.083012 -0.052716 -0.010679"/>
  <parent link="leg_2_femur_1"/>
  <child link="leg_2_motor__2__1"/>
  <axis xyz="-0.001736 -0.009848 -0.0"/>
</joint>
<transmission name="Rev49_tran">
  <type>transmission_interface/SimpleTransmission</type>
  <joint name="Rev49">
    <hardwareInterface>PositionJointInterface</hardwareInterface>
  </joint>
  <actuator name="Rev49_actr">
    <hardwareInterface>PositionJointInterface</hardwareInterface>
    <mechanicalReduction>1</mechanicalReduction>
  </actuator>
</transmission>
<joint name="Rev50" type="continuous">
  <origin rpy="0 0 0" xyz="0.096035 -0.021145 -0.010679"/>
  <parent link="leg_3_femur_1"/>
  <child link="leg_3_motor__2__1"/>
  <axis xyz="0.001736 -0.009848 -0.0"/>
</joint>
<transmission name="Rev50_tran">
  <type>transmission_interface/SimpleTransmission</type>
  <joint name="Rev50">
    <hardwareInterface>PositionJointInterface</hardwareInterface>
  </joint>
  <actuator name="Rev50_actr">
    <hardwareInterface>PositionJointInterface</hardwareInterface>
    <mechanicalReduction>1</mechanicalReduction>
  </actuator>
</transmission>
<joint name="Rev51" type="continuous">
  <origin rpy="0 0 0" xyz="0.090795 0.037763 -0.010679"/>
  <parent link="leg_4_femur_1"/>
  <child link="leg_4_motor__2__1"/>
  <axis xyz="0.007071 -0.007071 -0.0"/>
</joint>
<transmission name="Rev51_tran">
  <type>transmission_interface/SimpleTransmission</type>
  <joint name="Rev51">
    <hardwareInterface>PositionJointInterface</hardwareInterface>
  </joint>
  <actuator name="Rev51_actr">
    <hardwareInterface>PositionJointInterface</hardwareInterface>
    <mechanicalReduction>1</mechanicalReduction>
  </actuator>
</transmission>
<joint name="Rev52" type="continuous">
  <origin rpy="0 0 0" xyz="-0.066755 0.061805 -0.010679"/>
  <parent link="leg_5_femur_1"/>
  <child link="leg_5_motor__2__1"/>
  <axis xyz="0.007071 0.007071 -0.0"/>
</joint>
<transmission name="Rev52_tran">
  <type>transmission_interface/SimpleTransmission</type>
  <joint name="Rev52">
    <hardwareInterface>PositionJointInterface</hardwareInterface>
  </joint>
  <actuator name="Rev52_actr">
    <hardwareInterface>PositionJointInterface</hardwareInterface>
    <mechanicalReduction>1</mechanicalReduction>
  </actuator>
</transmission>
<joint name="Rev53" type="continuous">
  <origin rpy="0 0 0" xyz="-0.090131 0.012339 -0.010679"/>
  <parent link="leg_6_femur_1"/>
  <child link="leg_6_motor__2__1"/>
  <axis xyz="0.001736 0.009848 -0.0"/>
</joint>
<transmission name="Rev53_tran">
  <type>transmission_interface/SimpleTransmission</type>
  <joint name="Rev53">
    <hardwareInterface>PositionJointInterface</hardwareInterface>
  </joint>
  <actuator name="Rev53_actr">
    <hardwareInterface>PositionJointInterface</hardwareInterface>
    <mechanicalReduction>1</mechanicalReduction>
  </actuator>
</transmission>
<joint name="Rev54" type="continuous">
  <origin rpy="0 0 0" xyz="-0.088916 -0.019233 -0.010679"/>
  <parent link="leg_7_femur_1"/>
  <child link="leg_7_motor__2__1"/>
  <axis xyz="-0.001736 0.009848 -0.0"/>
</joint>
<transmission name="Rev54_tran">
  <type>transmission_interface/SimpleTransmission</type>
  <joint name="Rev54">
    <hardwareInterface>PositionJointInterface</hardwareInterface>
  </joint>
  <actuator name="Rev54_actr">
    <hardwareInterface>PositionJointInterface</hardwareInterface>
    <mechanicalReduction>1</mechanicalReduction>
  </actuator>
</transmission>
<joint name="Rev55" type="continuous">
  <origin rpy="0 0 0" xyz="-0.061805 -0.066755 -0.010679"/>
  <parent link="leg_8_femur_1"/>
  <child link="leg_8_motor__2__1"/>
  <axis xyz="-0.007071 0.007071 -0.0"/>
</joint>
<transmission name="Rev55_tran">
  <type>transmission_interface/SimpleTransmission</type>
  <joint name="Rev55">
    <hardwareInterface>PositionJointInterface</hardwareInterface>
  </joint>
  <actuator name="Rev55_actr">
    <hardwareInterface>PositionJointInterface</hardwareInterface>
    <mechanicalReduction>1</mechanicalReduction>
  </actuator>
</transmission>
<joint name="Rigid57" type="fixed">
  <origin rpy="0 0 0" xyz="-0.025456 -0.021213 0.0105"/>
  <parent link="leg_8_motor__2__1"/>
  <child link="leg_8_tibia_1"/>
</joint>
<transmission name="Rigid57_tran">
  <type>transmission_interface/SimpleTransmission</type>
  <joint name="Rigid57">
    <hardwareInterface>PositionJointInterface</hardwareInterface>
  </joint>
  <actuator name="Rigid57_actr">
    <hardwareInterface>PositionJointInterface</hardwareInterface>
    <mechanicalReduction>1</mechanicalReduction>
  </actuator>
</transmission>
<joint name="Rigid59" type="fixed">
  <origin rpy="0 0 0" xyz="-0.031978 0.008684 0.0105"/>
  <parent link="leg_6_motor__2__1"/>
  <child link="leg_6_tibia_1"/>
</joint>
<transmission name="Rigid59_tran">
  <type>transmission_interface/SimpleTransmission</type>
  <joint name="Rigid59">
    <hardwareInterface>PositionJointInterface</hardwareInterface>
  </joint>
  <actuator name="Rigid59_actr">
    <hardwareInterface>PositionJointInterface</hardwareInterface>
    <mechanicalReduction>1</mechanicalReduction>
  </actuator>
</transmission>
<joint name="Rigid60" type="fixed">
  <origin rpy="0 0 0" xyz="-0.021213 0.025455 0.0105"/>
  <parent link="leg_5_motor__2__1"/>
  <child link="leg_5_tibia_1"/>
</joint>
<transmission name="Rigid60_tran">
  <type>transmission_interface/SimpleTransmission</type>
  <joint name="Rigid60">
    <hardwareInterface>PositionJointInterface</hardwareInterface>
  </joint>
  <actuator name="Rigid60_actr">
    <hardwareInterface>PositionJointInterface</hardwareInterface>
    <mechanicalReduction>1</mechanicalReduction>
  </actuator>
</transmission>
<joint name="Rigid61" type="fixed">
  <origin rpy="0 0 0" xyz="-0.003535 0.050204 0.0105"/>
  <parent link="leg_4_motor__2__1"/>
  <child link="leg_4_tibia_1"/>
</joint>
<transmission name="Rigid61_tran">
  <type>transmission_interface/SimpleTransmission</type>
  <joint name="Rigid61">
    <hardwareInterface>PositionJointInterface</hardwareInterface>
  </joint>
  <actuator name="Rigid61_actr">
    <hardwareInterface>PositionJointInterface</hardwareInterface>
    <mechanicalReduction>1</mechanicalReduction>
  </actuator>
</transmission>
<joint name="Rigid62" type="fixed">
  <origin rpy="0 0 0" xyz="0.025901 0.043154 0.0105"/>
  <parent link="leg_3_motor__2__1"/>
  <child link="leg_3_tibia_1"/>
</joint>
<transmission name="Rigid62_tran">
  <type>transmission_interface/SimpleTransmission</type>
  <joint name="Rigid62">
    <hardwareInterface>PositionJointInterface</hardwareInterface>
  </joint>
  <actuator name="Rigid62_actr">
    <hardwareInterface>PositionJointInterface</hardwareInterface>
    <mechanicalReduction>1</mechanicalReduction>
  </actuator>
</transmission>
<joint name="Rigid63" type="fixed">
  <origin rpy="0 0 0" xyz="0.039097 0.031693 0.0105"/>
  <parent link="leg_2_motor__2__1"/>
  <child link="leg_2_tibia_1"/>
</joint>
<transmission name="Rigid63_tran">
  <type>transmission_interface/SimpleTransmission</type>
  <joint name="Rigid63">
    <hardwareInterface>PositionJointInterface</hardwareInterface>
  </joint>
  <actuator name="Rigid63_actr">
    <hardwareInterface>PositionJointInterface</hardwareInterface>
    <mechanicalReduction>1</mechanicalReduction>
  </actuator>
</transmission>
<joint name="Rigid64" type="fixed">
  <origin rpy="0 0 0" xyz="0.050205 0.003536 0.0105"/>
  <parent link="leg_1_motor__2__1"/>
  <child link="leg_1_tibia_1"/>
</joint>
<transmission name="Rigid64_tran">
  <type>transmission_interface/SimpleTransmission</type>
  <joint name="Rigid64">
    <hardwareInterface>PositionJointInterface</hardwareInterface>
  </joint>
  <actuator name="Rigid64_actr">
    <hardwareInterface>PositionJointInterface</hardwareInterface>
    <mechanicalReduction>1</mechanicalReduction>
  </actuator>
</transmission>
<joint name="Rev65" type="continuous">
  <origin rpy="0 0 0" xyz="-0.0105 -0.03 0.003"/>
  <parent link="tail_motor_1"/>
  <child link="Component62_1"/>
  <axis xyz="-0.0 0.0 -0.01"/>
</joint>
<transmission name="Rev65_tran">
  <type>transmission_interface/SimpleTransmission</type>
  <joint name="Rev65">
    <hardwareInterface>PositionJointInterface</hardwareInterface>
  </joint>
  <actuator name="Rev65_actr">
    <hardwareInterface>PositionJointInterface</hardwareInterface>
    <mechanicalReduction>1</mechanicalReduction>
  </actuator>
</transmission>
<joint name="Rev66" type="continuous">
  <origin rpy="0 0 0" xyz="0.0105 0.03 0.003"/>
  <parent link="head_motor_pan_1"/>
  <child link="head_neck_1"/>
  <axis xyz="-0.0 0.0 -0.01"/>
</joint>
<transmission name="Rev66_tran">
  <type>transmission_interface/SimpleTransmission</type>
  <joint name="Rev66">
    <hardwareInterface>PositionJointInterface</hardwareInterface>
  </joint>
  <actuator name="Rev66_actr">
    <hardwareInterface>PositionJointInterface</hardwareInterface>
    <mechanicalReduction>1</mechanicalReduction>
  </actuator>
</transmission>
<joint name="Rigid67" type="fixed">
  <origin rpy="0 0 0" xyz="-0.03302 -0.002776 0.0105"/>
  <parent link="leg_7_motor__1__1"/>
  <child link="leg_7_femur_1"/>
</joint>
<transmission name="Rigid67_tran">
  <type>transmission_interface/SimpleTransmission</type>
  <joint name="Rigid67">
    <hardwareInterface>PositionJointInterface</hardwareInterface>
  </joint>
  <actuator name="Rigid67_actr">
    <hardwareInterface>PositionJointInterface</hardwareInterface>
    <mechanicalReduction>1</mechanicalReduction>
  </actuator>
</transmission>
<joint name="Rigid68" type="fixed">
  <origin rpy="0 0 0" xyz="-0.033019 -0.002776 0.0105"/>
  <parent link="leg_7_motor__2__1"/>
  <child link="leg_7_tibia_1"/>
</joint>
<transmission name="Rigid68_tran">
  <type>transmission_interface/SimpleTransmission</type>
  <joint name="Rigid68">
    <hardwareInterface>PositionJointInterface</hardwareInterface>
  </joint>
  <actuator name="Rigid68_actr">
    <hardwareInterface>PositionJointInterface</hardwareInterface>
    <mechanicalReduction>1</mechanicalReduction>
  </actuator>
</transmission>
<joint name="Rev69" type="continuous">
  <origin rpy="0 0 0" xyz="-0.025 0.045 -0.010622"/>
  <parent link="head_neck_1"/>
  <child link="head_link_1"/>
  <axis xyz="0.01 -0.0 0.0"/>
</joint>
<transmission name="Rev69_tran">
  <type>transmission_interface/SimpleTransmission</type>
  <joint name="Rev69">
    <hardwareInterface>PositionJointInterface</hardwareInterface>
  </joint>
  <actuator name="Rev69_actr">
    <hardwareInterface>PositionJointInterface</hardwareInterface>
    <mechanicalReduction>1</mechanicalReduction>
  </actuator>
</transmission>
<gazebo>
  <plugin filename="libgazebo_ros_control.so" name="control"/>
</gazebo>
</robot>
